Workbook

Sheet Sheet2
A3: Row Labels | B3: Count of ¿En qué país resides?
A4: Disminuyen mi productividad | B4: 11
A5: Mejoran mi productividad | B5: 99
A6: Mejoran mucho mi productividad | B6: 37
A7: No afectan a mi productividad | B7: 85
A8: Grand Total | B8: 232
A12: Row Labels | B12: Count of ¿En qué país resides?
A13: Igual que cuando iba todos los días a la oficina | B13: 88
A14: Mayor que cuando iba todos los días a la oficina | B14: 52
A15: Menor que cuando iba todos los días a la oficina | B15: 37
A16: Mucho mayor que cuando iba todos los días a la oficina | B16: 18
A17: Mucho menor que cuando iba todos los días a la oficina | B17: 9
A18: No tengo la información para contestar a la pregunta | B18: 28
A19: Grand Total | B19: 232
A21: Row Labels | B21: Count of ¿En qué país resides?
A22: Igual que cuando iba todos los días a la oficina | B22: 86
A23: Mayor que cuando iba todos los días a la oficina | B23: 59
A24: Menor que cuando iba todos los días a la oficina | B24: 22
A25: Mucho Mejor que cuando iba todos los días a la oficina | B25: 61
A26: Mucho menor que cuando iba todos los días a la oficina | B26: 4
A27: Grand Total | B27: 232

Sheet Datos
A1: Marca temporal | B1: ¿En qué país resides? | C1: Tu edad está dentro del rango: | D1: ¿Tu género es? | E1: Indica tu nivel de estudios: | F1: Indica los años de experiencia trabajando en empresas de desarrollo de software: | G1: Por favor indica el puesto que ocupabas cuando trabajabas presencialmente en la empresa: | H1: Por favor indica el puesto que ocupas actualmente en la empresa: | I1: Tamaño de la compañía | J1: Tipo de empresa: | K1: Tu empresa es: | L1: ¿En tu trabajo te comunicas con personas de distintos países? | M1: NIVEL HOMEOFFICE | N1: ¿Cuántos días a la semana trabajas desde casa actualmente? | O1: ¿Cuántos días a la semana vas a la oficina actualmente? | P1: ¿Qué modalidad de trabajo prefieres? | Q1: La modalidad que actualmente tienes fue: | R1: Trabajo la misma cantidad de horas que cuando trabajaba todos los días en la oficina | S1: El intercambio de conocimiento con mis compañeros de proyecto es ahora: | T1: La comunicación en general con mis compañeros de proyecto es ahora | U1: La comunicación con mis jefes es ahora | V1: Tus horarios de trabajo ahora son: | W1: Mis reuniones ahora son: | X1: El cansancio después de una reunión online es ahora: | Y1: Siento que mi rendimiento ahora es: | Z1: Siento que la productividad de mi equipo es: | AA1: Siento que la capacidad de mi equipo para cumplir hitos es: | AB1: Siento que mi concentración cuando estoy trabajando es: | AC1: Siento que la velocidad de mi conexión a Internet es | AD1: Siento que la eficiencia de la conexión a Internet me influye: | AE1: Las herramientas de comunicación (Teams, Zoom, Slack,...) utilizadas por mi empresa, desde casa: | AF1: Siento que la facilidad para compartir conocimiento ahora es: | AG1: Siento que el impacto de la rotación de personal en la empresa ahora es: | AH1: Siento que la falta de compromiso por parte de los empleados, afecta a la productividad: | AI1: Siento que el hecho de trabajar con personas de distintas culturas afecta a la productividad: | AJ1: Siento que el hecho de trabajar con personas que tienen otros horarios afecta a la productividad | AK1: Siento que el hecho de trabajar con personas que se encuentran geográficamente distribuidas afecta a la productividad: | AL1: Siento que la falta de confianza entre los miembros del equipo afecta la productividad | AM1: Siento que la falta de colaboración entre los miembros del equipo afecta la productividad: | AN1: Siento que la falta de relaciones personales entre los miembros del equipo afecta la productividad: | AO1: Siento que la falta de cohesión y de espíritu de grupo afecta la productividad | AP1: Siento que los problemas de liderazgo afectan la productividad | AQ1: Siento que el nivel de la definición de los requisitos de software y su calidad son ahora: | AR1: Siento que el control de los cambios de los requisitos es ahora: | AS1: Siento que la cantidad de personal cualificado en la empresa es ahora: | AT1: Siento que mi nivel de estrés es: | AU1: Siento que mi nivel de confianza para enfrentarme a los retos del trabajo es: | AV1: Siento que mis reacciones de enojo o molestia ahora son: | AW1: Siento que mi nivel de frustración con relación al trabajo es: | AX1: Siento que el nivel de presión por terminar las tareas ahora es: | AY1: Siento que la flexibilidad de mi trabajo ahora es: | AZ1: Siento que los problemas tecnológicos ahora son: | BA1: Siento que la facilidad para trabajar en equipos distribuidos es: | BB1: Siento que los problemas que aparecen por las diferencias culturales ahora son: | BC1: Siento que la aplicación de metodología ágiles ahora es: | BD1: Siento que los problemas de comunicación ahora son: | BE1: Siento que los problemas por usar distintos idiomas ahora son: | BF1: Siento que el hecho de trabajar con personas que tienen otros horarios afecta a mi estrés: | BG1: Siento que la generación de confianza entre los miembros del equipo ahora es: | BH1: Siento que las interrupciones externas ahora son: | BI1: Siento que ahora mi manejo del tiempo en general es: | BJ1: Siento que la falta de compañerismo ahora es: | BK1: Siento que los problemas de coordinación afectan a mi estrés: | BL1: Siento que los problemas vinculados con la gestión del proyecto ahora son: | BM1: Siento que la asignación de tareas entre los miembros del equipo ahora es: | BN1: Siento que mi nivel de motivación en el trabajo es: | BO1: Mi concentración ahora cuando estoy trabajando es: | BP1: Mi comodidad ahora cuando estoy trabajando es: | BQ1: Mi seguridad/ confianza a la hora de preguntar a un compañero ahora es: | BR1: Mi confianza para hacer preguntas a un superior ahora es: | BS1: Mi habilidad para resolver problemas ahora es: | BT1: En términos de disfrute en el trabajo siento que ahora es: | BU1: Siento que el nivel de interés hacia mi trabajo ahora es: | BV1: Siento que la falta de conocimiento sobre el rol de cada miembro del equipo ahora es: | BW1: Siento que mi empresa me aprecia: | BX1: Siento que las acciones de motivación de personal de mi empresa son: | BY1: Siento que la calidad del desarrollo de software es ahora: | BZ1: Siento que el equilibrio vida personal - trabajo es ahora: | CA1: Siento que ahora la retroalimentación que recibo por parte de mis compañeros y superiores es: | CB1: Siento que mi nivel de aburrimiento en el trabajo es ahora: | CC1: Siento que mi nivel de atención a cada individuo es ahora: | CD1: Siento que mi miedo a perder el trabajo es ahora: | CE1: Siento que el ambiente de trabajo ahora es: | CF1: Siento que mi nivel de influencia en mi equipo de trabajo es ahora: | CG1: Siento que la facilidad para desarrollar relaciones personales entre los compañeros de trabajo es ahora | CH1: Siento que la participación de los miembros en los proyectos de mi equipo es ahora: | CI1: Siento que el nivel de autonomía en el trabajo es ahora | CJ1: Siento que el nivel de relaciones conflictivas entre compañeros es ahora: | CK1: Siento que los problemas relacionados con el liderazgo compartido son ahora: | CL1: El sentimiento de pertenencia a mi empresa es ahora | CM1: Siento que mi creatividad es: | CN1: Correo electrónico para recibir resultados (opcional) | CO1: Tam_Empresa | CP1: Lead
A2: 45594.111 | B2: Argentina | C2: <35 años | D2: Masculino | E2: Universitarios completo | F2: 5-10 años | G2: Desarrollador de Software | H2: Líder Técnico | I2: >500 empleados. | J2: Empresa que desarrolla software a medida partiendo desde cero | K2: Multinacional | L2: Muy Frecuentemente | M2: Alto | N2: >5 días | O2: Ninguno | P2: Remota ( todos los días en casa) | Q2: Consensuada por las dos partes | R2: En desacuerdo | S2: Igual que cuando iba todos los días a la oficina | T2: Igual que cuando iba todos los días a la oficina | U2: Mayor que cuando iba todos los días a la oficina | V2: Diferentes que cuando iba todos los días a la oficina, ahora necesito menos horas para hacer lo mismo | W2: Todas por videoconferencia | X2: Igual que cuando eran en la oficina | Y2: Mayor que cuando iba todos los días a la oficina | Z2: Mayor que cuando iba todos los días a la oficina | AA2: Mayor que cuando iba todos los días a la oficina | AB2: Mucho Mayor que cuando iba todos los días a la oficina | AC2: Mucho Mejor que cuando iba todos los días a la oficina | AD2: Mejora mucho mi desempeño en el trabajo | AE2: Mejoran mi productividad | AF2: Menor que cuando iba todos los días a la oficina | AG2: Mucho mayor que cuando iba todos los días a la oficina | AH2: Igual que cuando iba todos los días a la oficina | AI2: Igual que cuando iba todos los días a la oficina | AJ2: Mucho menos que cuando iba todos los días a la oficina | AK2: Mucho menos que cuando iba todos los días a la oficina | AL2: Más que cuando iba todos los días a la oficina | AM2: Igual que cuando iba todos los días a la oficina | AN2: Mas que cuando iba todos los días a la oficina | AO2: Igual que cuando iba todos los días a la oficina | AP2: Mas que cuando iba todos los días a la oficina | AQ2: Mayores que cuando iba todos los días a la oficina | AR2: Mucho Mayor que cuando iba todos los días a la oficina | AS2: Mucho Mayor que cuando iba todos los días a la oficina | AT2: Igual que cuando iba todos los días a la oficina | AU2: Mayor que cuando iba todos los días a la oficina | AV2: Menor que cuando iba todos los días a la oficina | AW2: Menor que cuando iba todos los días a la oficina | AX2: Mayor que cuando iba todos los días a la oficina | AY2: Mucho mayor que cuando iba todos los días a la oficina | AZ2: Menores que cuando iba todos los días a la oficina | BA2: Mucho mayor que cuando iba todos los días a la oficina | BB2: Iguales que cuando iba todos los días a la oficina | BC2: Mucho mayor que cuando iba todos los días a la oficina | BD2: Menores que cuando iba todos los días a la oficina | BE2: Menores que cuando iba todos los días a la oficina | BF2: Igual que cuando iba todos los días a la oficina | BG2: Menor que cuando iba todos los días a la oficina | BH2: Mayores que cuando iba todos los días a la oficina | BI2: Mucho mayor que cuando iba todos los días a la oficina | BJ2: Menor que cuando iba todos los días a la oficina | BK2: Igual que cuando iba todos los días a la oficina | BL2: Iguales que cuando iba todos los días a la oficina | BM2: Mejor que cuando iba todos los días a la oficina | BN2: Mucho Mayor que cuando iba todos los días a la oficina | BO2: Mayor que cuando iba todos los días a la oficina | BP2: Mayor que cuando iba todos los días a la oficina | BQ2: Menor que cuando iba todos los días a la oficina | BR2: Mayor que cuando iba todos los días a la oficina | BS2: Igual que cuando iba todos los días a la oficina | BT2: Mucho Mayor que cuando iba todos los días a la oficina | BU2: Igual que cuando iba todos los días a la oficina | BV2: Mayor que cuando iba todos los días a la oficina | BW2: Menos que cuando iba todos los días a la oficina | BX2: Iguales que cuando iba todos los días a la oficina | BY2: Mayor que cuando iba todos los días a la oficina | BZ2: Mucho Mayor que cuando iba todos los días a la oficina | CA2: Mayor que cuando iba todos los días a la oficina | CB2: Menor que cuando iba todos los días a la oficina | CC2: Mayor que cuando iba todos los días a la oficina | CD2: Mayor que cuando iba todos los días a la oficina | CE2: Igual que cuando iba todos los días a la oficina | CF2: Menor que cuando iba todos los días a la oficina | CG2: Menor que cuando iba todos los días a la oficina | CH2: Mayor que cuando iba todos los días a la oficina | CI2: Mucho Mayor que cuando iba todos los días a la oficina | CJ2: Mucho menor que cuando iba todos los días a la oficina | CK2: Menores que cuando iba todos los días a la oficina | CL2: Igual que cuando iba todos los días a la oficina | CM2: Igual que cuando iba todos los días a la oficina | CN2: juan.delafuente@fi.uncoma.edu.ar | CO2: 301+ empleados | CP2: =IFERROR(VLOOKUP(H2,'Lista Lideres'!$A$1:$B$350,2,0),0) -> 1
A3: 45569.678 | B3: Argentina | C3: <35 años | D3: Femenino | E3: Universitarios | F3: <5 años | G3: Ing. En yacimiento digital | H3: Developer | I3: >500 empleados. | J3: Empresa que desarrolla software a medida partiendo desde cero | K3: Multinacional | L3: A veces | M3: Alto | N3: >5 días | O3: Ninguno | P3: Remota ( todos los días en casa) | Q3: Consensuada por las dos partes | R3: En desacuerdo | S3: Igual que cuando iba todos los días a la oficina | T3: Igual que cuando iba todos los días a la oficina | U3: Igual que cuando iba todos los días a la oficina | V3: Muy diferentes que cuando iba todos los días a la oficina, ahora necesito muchas menos horas para hacer lo mismo | W3: Todas por videoconferencia | X3: Igual que cuando eran en la oficina | Y3: Mayor que cuando iba todos los días a la oficina | Z3: Mucho Mayor que cuando iba todos los días a la oficina | AA3: Mucho Mayor que cuando iba todos los días a la oficina | AB3: Mucho Mayor que cuando iba todos los días a la oficina | AC3: Igual que cuando iba todos los días a la oficina | AD3: Mejora mi desempeño en el trabajo | AE3: No afectan a mi productividad | AF3: Mayor que cuando iba todos los días a la oficina | AG3: Mayor que cuando iba todos los días a la oficina | AH3: Igual que cuando iba todos los días a la oficina | AI3: Igual que cuando iba todos los días a la oficina | AJ3: Igual que cuando iba todos los días a la oficina | AK3: Igual que cuando iba todos los días a la oficina | AL3: Igual que cuando iba todos los días a la oficina | AM3: Menos que cuando iba todos los días a la oficina | AN3: Igual que cuando iba todos los días a la oficina | AO3: Igual que cuando iba todos los días a la oficina | AP3: Igual que cuando iba todos los días a la oficina | AQ3: Mayores que cuando iba todos los días a la oficina | AR3: Igual que cuando iba todos los días a la oficina | AS3: Mayor que cuando iba todos los días a la oficina | AT3: Menor que cuando iba todos los días a la oficina | AU3: Mayor que cuando iba todos los días a la oficina | AV3: Igual que cuando iba todos los días a la oficina | AW3: Menor que cuando iba todos los días a la oficina | AX3: Igual que cuando iba todos los días a la oficina | AY3: Mucho mayor que cuando iba todos los días a la oficina | AZ3: Iguales que cuando iba todos los días a la oficina | BA3: Mayor que cuando iba todos los días a la oficina | BB3: No hay diferencias culturales en mi equipo | BC3: Mayor que cuando iba todos los días a la oficina | BD3: Iguales que cuando iba todos los días a la oficina | BE3: No tengo que utilizar diferentes idiomas en mi trabajo | BF3: No trabajo con personas con distintos horarios | BG3: Igual que cuando iba todos los días a la oficina | BH3: Mucho menores que cuando iba todos los días a la oficina | BI3: Mucho mayor que cuando iba todos los días a la oficina | BJ3: Menor que cuando iba todos los días a la oficina | BK3: Mucho menos que cuando iba todos los días a la oficina | BL3: Iguales que cuando iba todos los días a la oficina | BM3: Mejor que cuando iba todos los días a la oficina | BN3: Mayor que cuando iba todos los días a la oficina | BO3: Mucho Mayor que cuando iba todos los días a la oficina | BP3: Mucho mayor que cuando iba todos los días a la oficina | BQ3: Mayor que cuando iba todos los días a la oficina | BR3: Igual que cuando iba todos los días a la oficina | BS3: Mayor que cuando iba todos los días a la oficina | BT3: Mayor que cuando iba todos los días a la oficina | BU3: Igual que cuando iba todos los días a la oficina | BV3: Menor que cuando iba todos los días a la oficina | BW3: Igual que cuando iba todos los días a la oficina | BX3: Iguales que cuando iba todos los días a la oficina | BY3: Mayor que cuando iba todos los días a la oficina | BZ3: Mucho Mayor que cuando iba todos los días a la oficina | CA3: Igual que cuando iba todos los días a la oficina | CB3: Igual que cuando iba todos los días a la oficina | CC3: Igual que cuando iba todos los días a la oficina | CD3: Igual que cuando iba todos los días a la oficina | CE3: Mejor que cuando iba todos los días a la oficina | CF3: Igual que cuando iba todos los días a la oficina | CG3: Igual que cuando iba todos los días a la oficina | CH3: Igual que cuando iba todos los días a la oficina | CI3: Mucho Mayor que cuando iba todos los días a la oficina | CJ3: Igual que cuando iba todos los días a la oficina | CK3: Iguales que cuando iba todos los días a la oficina | CL3: Igual que cuando iba todos los días a la oficina | CM3: Igual que cuando iba todos los días a la oficina | CO3: 301+ empleados | CP3: =IFERROR(VLOOKUP(H3,'Lista Lideres'!$A$1:$B$350,2,0),0) -> 0
A4: 45572.098 | B4: Argentina | C4: <35 años | D4: Femenino | E4: universitario | F4: 21-30 años | G4: Referente IT | H4: COO | I4: <50 empleados | J4: Empresa que desarrolla software a medida partiendo desde cero | K4: Multinacional | L4: Casi Nunca | M4: Alto | N4: >5 días | O4: Ninguno | P4: Remota ( todos los días en casa) | Q4: Decidida por ti | R4: En desacuerdo | S4: Mayor que cuando iba todos los días a la oficina | T4: Mayor que cuando iba todos los días a la oficina | U4: Mayor que cuando iba todos los días a la oficina | V4: Diferentes que cuando iba todos los días a la oficina, ahora necesito menos horas para hacer lo mismo | W4: Casi todas por videoconferencia | X4: Menor que cuando eran en la oficina | Y4: Mayor que cuando iba todos los días a la oficina | Z4: Mucho Mayor que cuando iba todos los días a la oficina | AA4: Mucho Mayor que cuando iba todos los días a la oficina | AB4: Mayor que cuando iba todos los días a la oficina | AC4: Mucho Mejor que cuando iba todos los días a la oficina | AD4: Mejora mucho mi desempeño en el trabajo | AE4: No afectan a mi productividad | AF4: Igual que cuando iba todos los días a la oficina | AG4: Igual que cuando iba todos los días a la oficina | AH4: Igual que cuando iba todos los días a la oficina | AI4: No trabajo con personas de distintas culturas | AJ4: Mucho menos que cuando iba todos los días a la oficina | AK4: Mucho menos que cuando iba todos los días a la oficina | AL4: Igual que cuando iba todos los días a la oficina | AM4: Igual que cuando iba todos los días a la oficina | AN4: Igual que cuando iba todos los días a la oficina | AO4: Igual que cuando iba todos los días a la oficina | AP4: Igual que cuando iba todos los días a la oficina | AQ4: Menores que cuando iba todos los días a la oficina | AR4: Igual que cuando iba todos los días a la oficina | AS4: Igual que cuando iba todos los días a la oficina | AT4: Mucho menor que cuando iba todos los días a la oficina | AU4: Igual que cuando iba todos los días a la oficina | AV4: Igual que cuando iba todos los días a la oficina | AW4: Igual que cuando iba todos los días a la oficina | AX4: Igual que cuando iba todos los días a la oficina | AY4: Mucho mayor que cuando iba todos los días a la oficina | AZ4: Mucho menores que cuando iba todos los días a la oficina | BA4: Mucho menor que cuando iba todos los días a la oficina | BB4: No hay diferencias culturales en mi equipo | BC4: Mayor que cuando iba todos los días a la oficina | BD4: Iguales que cuando iba todos los días a la oficina | BE4: No tengo que utilizar diferentes idiomas en mi trabajo | BF4: Menos que cuando iba todos los días a la oficina | BG4: Igual que cuando iba todos los días a la oficina | BH4: Mucho menores que cuando iba todos los días a la oficina | BI4: Mucho mayor que cuando iba todos los días a la oficina | BJ4: Menor que cuando iba todos los días a la oficina | BK4: Menos que cuando iba todos los días a la oficina | BL4: Menores que cuando iba todos los días a la oficina | BM4: Igual que cuando iba todos los días a la oficina | BN4: Mayor que cuando iba todos los días a la oficina | BO4: Mayor que cuando iba todos los días a la oficina | BP4: Mayor que cuando iba todos los días a la oficina | BQ4: Igual que cuando iba todos los días a la oficina | BR4: Igual que cuando iba todos los días a la oficina | BS4: Igual que cuando iba todos los días a la oficina | BT4: Mayor que cuando iba todos los días a la oficina | BU4: Igual que cuando iba todos los días a la oficina | BV4: Igual que cuando iba todos los días a la oficina | BW4: Menos que cuando iba todos los días a la oficina | BX4: Iguales que cuando iba todos los días a la oficina | BY4: Mayor que cuando iba todos los días a la oficina | BZ4: Mucho Mayor que cuando iba todos los días a la oficina | CA4: Mayor que cuando iba todos los días a la oficina | CB4: Menor que cuando iba todos los días a la oficina | CC4: Menor que cuando iba todos los días a la oficina | CD4: Menor que cuando iba todos los días a la oficina | CE4: Mejor que cuando iba todos los días a la oficina | CF4: Mayor que cuando iba todos los días a la oficina | CG4: Igual que cuando iba todos los días a la oficina | CH4: Mayor que cuando iba todos los días a la oficina | CI4: Mayor que cuando iba todos los días a la oficina | CJ4: Menor que cuando iba todos los días a la oficina | CK4: Menores que cuando iba todos los días a la oficina | CL4: Menor que cuando iba todos los días a la oficina | CM4: Mayor que cuando iba todos los días a la oficina | CN4: baeza.natalia@gmail.com | CO4: <301 empleados | CP4: =IFERROR(VLOOKUP(H4,'Lista Lideres'!$A$1:$B$350,2,0),0) -> 1
A5: 45596.597 | B5: Argentina | C5: <35 años | D5: Masculino | E5: Universitario completo | F5: 5-10 años | G5: Software Engineer | H5: Senior Software Engineer | I5: 51-150 empleados | J5: Empresa que desarrolla software a medida partiendo desde cero | K5: Multinacional | L5: Frecuentemente | M5: Alto | N5: >5 días | O5: Ninguno | P5: Remota ( todos los días en casa) | Q5: Impuesta por la empresa | R5: De acuerdo | S5: Mucho mayor que cuando iba todos los días a la oficina | T5: Menor que cuando iba todos los días a la oficina | U5: Igual que cuando iba todos los días a la oficina | V5: Iguales que cuando iba todos los días a la oficina | W5: Todas por videoconferencia | X5: Mucho menor que cuando eran en la oficina | Y5: Mucho Mayor que cuando iba todos los días a la oficina | Z5: Mayor que cuando iba todos los días a la oficina | AA5: Mayor que cuando iba todos los días a la oficina | AB5: Mucho Mayor que cuando iba todos los días a la oficina | AC5: Mucho Mejor que cuando iba todos los días a la oficina | AD5: No me influye | AE5: Mejoran mucho mi productividad | AF5: Mucho mayor que cuando iba todos los días a la oficina | AG5: Igual que cuando iba todos los días a la oficina | AH5: Igual que cuando iba todos los días a la oficina | AI5: Mucho menos que cuando iba todos los días a la oficina | AJ5: Mucho menos que cuando iba todos los días a la oficina | AK5: Mucho menos que cuando iba todos los días a la oficina | AL5: No tengo la información para contestar a la pregunta | AM5: Igual que cuando iba todos los días a la oficina | AN5: Mucho menos que cuando iba todos los días a la oficina | AO5: Igual que cuando iba todos los días a la oficina | AP5: Igual que cuando iba todos los días a la oficina | AQ5: Mayores que cuando iba todos los días a la oficina | AR5: Mayor que cuando iba todos los días a la oficina | AS5: Igual que cuando iba todos los días a la oficina | AT5: Mucho menor que cuando iba todos los días a la oficina | AU5: Mucho Mayor que cuando iba todos los días a la oficina | AV5: Mucho menor que cuando iba todos los días a la oficina | AW5: Mucho menor que cuando iba todos los días a la oficina | AX5: Igual que cuando iba todos los días a la oficina | AY5: Mayor que cuando iba todos los días a la oficina | AZ5: Menores que cuando iba todos los días a la oficina | BA5: Mayor que cuando iba todos los días a la oficina | BB5: Menores que cuando iba todos los días a la oficina | BC5: Igual que cuando iba todos los días a la oficina | BD5: Iguales que cuando iba todos los días a la oficina | BE5: Mucho menores que cuando iba todos los días a la oficina | BF5: Menos que cuando iba todos los días a la oficina | BG5: Igual que cuando iba todos los días a la oficina | BH5: Mucho menores que cuando iba todos los días a la oficina | BI5: Mucho mayor que cuando iba todos los días a la oficina | BJ5: Igual que cuando iba todos los días a la oficina | BK5: Igual que cuando iba todos los días a la oficina | BL5: Iguales que cuando iba todos los días a la oficina | BM5: Igual que cuando iba todos los días a la oficina | BN5: Mucho Mayor que cuando iba todos los días a la oficina | BO5: Igual que cuando iba todos los días a la oficina | BP5: Mucho mayor que cuando iba todos los días a la oficina | BQ5: Mucho Mayor que cuando iba todos los días a la oficina | BR5: Igual que cuando iba todos los días a la oficina | BS5: Mucho Mayor que cuando iba todos los días a la oficina | BT5: Mucho Mayor que cuando iba todos los días a la oficina | BU5: Menor que cuando iba todos los días a la oficina | BV5: Mayor que cuando iba todos los días a la oficina | BW5: Igual que cuando iba todos los días a la oficina | BX5: Iguales que cuando iba todos los días a la oficina | BY5: Mucho Mayor que cuando iba todos los días a la oficina | BZ5: Mucho Mayor que cuando iba todos los días a la oficina | CA5: Igual que cuando iba todos los días a la oficina | CB5: Menor que cuando iba todos los días a la oficina | CC5: Igual que cuando iba todos los días a la oficina | CD5: Mayor que cuando iba todos los días a la oficina | CE5: Mejor que cuando iba todos los días a la oficina | CF5: Menor que cuando iba todos los días a la oficina | CG5: Mucho menor que cuando iba todos los días a la oficina | CH5: Igual que cuando iba todos los días a la oficina | CI5: Mayor que cuando iba todos los días a la oficina | CJ5: Igual que cuando iba todos los días a la oficina | CK5: Iguales que cuando iba todos los días a la oficina | CL5: Igual que cuando iba todos los días a la oficina | CM5: Mucho mayor que cuando iba todos los días a la oficina | CO5: <301 empleados | CP5: =IFERROR(VLOOKUP(H5,'Lista Lideres'!$A$1:$B$350,2,0),0) -> 0
A6: 45573.743 | B6: Colombia | C6: <35 años | D6: Masculino | E6: Magister | F6: 11-20 años | G6: Arquitecto de Datos | H6: Arquitecto de Datos | I6: >500 empleados. | J6: Empresa que subcontrata (outsourcing) los servicios de otra del mismo país | K6: Nacional (múltiples sedes en el mismo país) | L6: A veces | M6: Alto | N6: >5 días | O6: Ninguno | P6: Híbrida casa (más días en casa que en la oficina) | Q6: Decidida por ti | R6: Totalmente de acuerdo | S6: Menor que cuando iba todos los días a la oficina | T6: Igual que cuando iba todos los días a la oficina | U6: Igual que cuando iba todos los días a la oficina | V6: Iguales que cuando iba todos los días a la oficina | W6: Todas por videoconferencia | X6: Igual que cuando eran en la oficina | Y6: Igual que cuando iba todos los días a la oficina | Z6: Igual que cuando iba todos los días a la oficina | AA6: Menor que cuando iba todos los días a la oficina | AB6: Igual que cuando iba todos los días a la oficina | AC6: Mucho Mejor que cuando iba todos los días a la oficina | AD6: Mejora mucho mi desempeño en el trabajo | AE6: No afectan a mi productividad | AF6: Mayor que cuando iba todos los días a la oficina | AG6: Mayor que cuando iba todos los días a la oficina | AH6: Más que cuando iba todos los días a la oficina | AI6: Igual que cuando iba todos los días a la oficina | AJ6: Mucho más que cuando iba todos los días a la oficina | AK6: Mucho más que cuando iba todos los días a la oficina | AL6: Igual que cuando iba todos los días a la oficina | AM6: Igual que cuando iba todos los días a la oficina | AN6: Mas que cuando iba todos los días a la oficina | AO6: Mas que cuando iba todos los días a la oficina | AP6: Mucho mas que cuando iba todos los días a la oficina | AQ6: Menores que cuando iba todos los días a la oficina | AR6: Igual que cuando iba todos los días a la oficina | AS6: Igual que cuando iba todos los días a la oficina | AT6: Igual que cuando iba todos los días a la oficina | AU6: Igual que cuando iba todos los días a la oficina | AV6: Igual que cuando iba todos los días a la oficina | AW6: Igual que cuando iba todos los días a la oficina | AX6: Igual que cuando iba todos los días a la oficina | AY6: Mucho mayor que cuando iba todos los días a la oficina | AZ6: Iguales que cuando iba todos los días a la oficina | BA6: Mucho mayor que cuando iba todos los días a la oficina | BB6: Iguales que cuando iba todos los días a la oficina | BC6: Igual que cuando iba todos los días a la oficina | BD6: Mayores que cuando iba todos los días a la oficina | BE6: Iguales que cuando iba todos los días a la oficina | BF6: Más que cuando iba todos los días a la oficina | BG6: Igual que cuando iba todos los días a la oficina | BH6: Iguales que cuando iba todos los días a la oficina | BI6: Mayor que cuando iba todos los días a la oficina | BJ6: Igual que cuando iba todos los días a la oficina | BK6: Mucho más que cuando iba todos los días a la oficina | BL6: Iguales que cuando iba todos los días a la oficina | BM6: Igual que cuando iba todos los días a la oficina | BN6: Igual que cuando iba todos los días a la oficina | BO6: Igual que cuando iba todos los días a la oficina | BP6: Mucho mayor que cuando iba todos los días a la oficina | BQ6: Igual que cuando iba todos los días a la oficina | BR6: Igual que cuando iba todos los días a la oficina | BS6: Igual que cuando iba todos los días a la oficina | BT6: Mucho Mayor que cuando iba todos los días a la oficina | BU6: Igual que cuando iba todos los días a la oficina | BV6: Igual que cuando iba todos los días a la oficina | BW6: Igual que cuando iba todos los días a la oficina | BX6: Iguales que cuando iba todos los días a la oficina | BY6: Igual que cuando iba todos los días a la oficina | BZ6: Mucho Mayor que cuando iba todos los días a la oficina | CA6: Igual que cuando iba todos los días a la oficina | CB6: Igual que cuando iba todos los días a la oficina | CC6: Igual que cuando iba todos los días a la oficina | CD6: Igual que cuando iba todos los días a la oficina | CE6: Igual que cuando iba todos los días a la oficina | CF6: Igual que cuando iba todos los días a la oficina | CG6: Igual que cuando iba todos los días a la oficina | CH6: Igual que cuando iba todos los días a la oficina | CI6: Igual que cuando iba todos los días a la oficina | CJ6: Igual que cuando iba todos los días a la oficina | CK6: Iguales que cuando iba todos los días a la oficina | CL6: Igual que cuando iba todos los días a la oficina | CM6: Mayor que cuando iba todos los días a la oficina | CN6: e.jayo@uniandes.edu.co | CO6: 301+ empleados | CP6: =IFERROR(VLOOKUP(H6,'Lista Lideres'!$A$1:$B$350,2,0),0) -> 0
A7: 45572.985 | B7: Colombia | C7: <35 años | D7: Masculino | E7: Pregrado | F7: 5-10 años | G7: Backend Developer | H7: Software Engineer | I7: 51-150 empleados | J7: Empresa que subcontrata (outsourcing) los servicios de otra empresa situada en otro país | K7: Multinacional | L7: Casi Nunca | M7: Alto | N7: >5 días | O7: Ninguno | P7: Remota ( todos los días en casa) | Q7: Impuesta por la empresa | R7: Totalmente en desacuerdo | S7: Menor que cuando iba todos los días a la oficina | T7: Mucho Mayor que cuando iba todos los días a la oficina | U7: Mucho Mayor que cuando iba todos los días a la oficina | V7: Muy diferentes que cuando iba todos los días a la oficina, ahora necesito muchas menos horas para hacer lo mismo | W7: Todas por videoconferencia | X7: Mucho menor que cuando eran en la oficina | Y7: Mucho Mayor que cuando iba todos los días a la oficina | Z7: Mucho Mayor que cuando iba todos los días a la oficina | AA7: Mucho Mayor que cuando iba todos los días a la oficina | AB7: Menor que cuando iba todos los días a la oficina | AC7: Mucho Mejor que cuando iba todos los días a la oficina | AD7: Mejora mucho mi desempeño en el trabajo | AE7: Disminuyen mi productividad | AF7: Igual que cuando iba todos los días a la oficina | AG7: No tengo la información para contestar a la pregunta | AH7: Mucho menos que cuando iba todos los días a la oficina | AI7: Más que cuando iba todos los días a la oficina | AJ7: Más que cuando iba todos los días a la oficina | AK7: Menos que cuando iba todos los días a la oficina | AL7: Mucho más que cuando iba todos los días a la oficina | AM7: Mas que cuando iba todos los días a la oficina | AN7: Mucho más que cuando iba todos los días a la oficina | AO7: Igual que cuando iba todos los días a la oficina | AP7: Igual que cuando iba todos los días a la oficina | AQ7: Iguales que cuando iba todos los días a la oficina | AR7: Igual que cuando iba todos los días a la oficina | AS7: Mucho Mayor que cuando iba todos los días a la oficina | AT7: Mucho menor que cuando iba todos los días a la oficina | AU7: Mucho Mayor que cuando iba todos los días a la oficina | AV7: Mucho menor que cuando iba todos los días a la oficina | AW7: Mucho menor que cuando iba todos los días a la oficina | AX7: Mucho menor que cuando iba todos los días a la oficina | AY7: Mucho mayor que cuando iba todos los días a la oficina | AZ7: Mucho menores que cuando iba todos los días a la oficina | BA7: Mucho mayor que cuando iba todos los días a la oficina | BB7: Iguales que cuando iba todos los días a la oficina | BC7: Mucho mayor que cuando iba todos los días a la oficina | BD7: Mayores que cuando iba todos los días a la oficina | BE7: No tengo que utilizar diferentes idiomas en mi trabajo | BF7: Más que cuando iba todos los días a la oficina | BG7: Menor que cuando iba todos los días a la oficina | BH7: Mucho menores que cuando iba todos los días a la oficina | BI7: Mucho mayor que cuando iba todos los días a la oficina | BJ7: Igual que cuando iba todos los días a la oficina | BK7: Mucho menos que cuando iba todos los días a la oficina | BL7: Menores que cuando iba todos los días a la oficina | BM7: Mucho mejor que cuando iba todos los días a la oficina | BN7: Mucho Mayor que cuando iba todos los días a la oficina | BO7: Igual que cuando iba todos los días a la oficina | BP7: Mucho mayor que cuando iba todos los días a la oficina | BQ7: Mucho Mayor que cuando iba todos los días a la oficina | BR7: Mucho Mayor que cuando iba todos los días a la oficina | BS7: Mucho Mayor que cuando iba todos los días a la oficina | BT7: Mucho Mayor que cuando iba todos los días a la oficina | BU7: Mucho menor que cuando iba todos los días a la oficina | BV7: Mucho menor que cuando iba todos los días a la oficina | BW7: Mucho menos que cuando iba todos los días a la oficina | BX7: Mucho menores que cuando iba todos los días a la oficina | BY7: Mucho Mayor que cuando iba todos los días a la oficina | BZ7: Mucho Mayor que cuando iba todos los días a la oficina | CA7: Igual que cuando iba todos los días a la oficina | CB7: Mucho menor que cuando iba todos los días a la oficina | CC7: Menor que cuando iba todos los días a la oficina | CD7: Mayor que cuando iba todos los días a la oficina | CE7: Mucho Mejor que cuando iba todos los días a la oficina | CF7: Mucho Mayor que cuando iba todos los días a la oficina | CG7: Mucho menor que cuando iba todos los días a la oficina | CH7: Mucho menor que cuando iba todos los días a la oficina | CI7: Mucho Mayor que cuando iba todos los días a la oficina | CJ7: Mucho menor que cuando iba todos los días a la oficina | CK7: Mucho menores que cuando iba todos los días a la oficina | CL7: Mucho menor que cuando iba todos los días a la oficina | CM7: Mucho mayor que cuando iba todos los días a la oficina | CO7: <301 empleados | CP7: =IFERROR(VLOOKUP(H7,'Lista Lideres'!$A$1:$B$350,2,0),0) -> 0
A8: 45573.063 | B8: Colombia | C8: <35 años | D8: Masculino | E8: Profesional | F8: 5-10 años | G8: Desarollador junior | H8: Líder técnico de desarrollo | I8: 151-300 empleados | J8: Empresa que desarrolla software a medida partiendo desde cero | K8: Local | L8: Casi Nunca | M8: Alto | N8: >5 días | O8: Ninguno | P8: Remota ( todos los días en casa) | Q8: Impuesta por la empresa | R8: Totalmente en desacuerdo | S8: Igual que cuando iba todos los días a la oficina | T8: Igual que cuando iba todos los días a la oficina | U8: Igual que cuando iba todos los días a la oficina | V8: Iguales que cuando iba todos los días a la oficina | W8: Todas por videoconferencia | X8: Igual que cuando eran en la oficina | Y8: Mayor que cuando iba todos los días a la oficina | Z8: Mucho Mayor que cuando iba todos los días a la oficina | AA8: Mayor que cuando iba todos los días a la oficina | AB8: Mayor que cuando iba todos los días a la oficina | AC8: Igual que cuando iba todos los días a la oficina | AD8: Mejora mi desempeño en el trabajo | AE8: Mejoran mi productividad | AF8: Igual que cuando iba todos los días a la oficina | AG8: Igual que cuando iba todos los días a la oficina | AH8: Igual que cuando iba todos los días a la oficina | AI8: Igual que cuando iba todos los días a la oficina | AJ8: Igual que cuando iba todos los días a la oficina | AK8: Igual que cuando iba todos los días a la oficina | AL8: Igual que cuando iba todos los días a la oficina | AM8: Igual que cuando iba todos los días a la oficina | AN8: Igual que cuando iba todos los días a la oficina | AO8: Igual que cuando iba todos los días a la oficina | AP8: Igual que cuando iba todos los días a la oficina | AQ8: Iguales que cuando iba todos los días a la oficina | AR8: Igual que cuando iba todos los días a la oficina | AS8: Igual que cuando iba todos los días a la oficina | AT8: Igual que cuando iba todos los días a la oficina | AU8: Igual que cuando iba todos los días a la oficina | AV8: Igual que cuando iba todos los días a la oficina | AW8: Igual que cuando iba todos los días a la oficina | AX8: Igual que cuando iba todos los días a la oficina | AY8: Igual que cuando iba todos los días a la oficina | AZ8: Iguales que cuando iba todos los días a la oficina | BA8: Igual que cuando iba todos los días a la oficina | BB8: Iguales que cuando iba todos los días a la oficina | BC8: Mayor que cuando iba todos los días a la oficina | BD8: Iguales que cuando iba todos los días a la oficina | BE8: Iguales que cuando iba todos los días a la oficina | BF8: Igual que cuando iba todos los días a la oficina | BG8: Igual que cuando iba todos los días a la oficina | BH8: Iguales que cuando iba todos los días a la oficina | BI8: Igual que cuando iba todos los días a la oficina | BJ8: Igual que cuando iba todos los días a la oficina | BK8: Igual que cuando iba todos los días a la oficina | BL8: Iguales que cuando iba todos los días a la oficina | BM8: Igual que cuando iba todos los días a la oficina | BN8: Igual que cuando iba todos los días a la oficina | BO8: Mayor que cuando iba todos los días a la oficina | BP8: Mayor que cuando iba todos los días a la oficina | BQ8: Igual que cuando iba todos los días a la oficina | BR8: Igual que cuando iba todos los días a la oficina | BS8: Igual que cuando iba todos los días a la oficina | BT8: Igual que cuando iba todos los días a la oficina | BU8: Igual que cuando iba todos los días a la oficina | BV8: Igual que cuando iba todos los días a la oficina | BW8: Igual que cuando iba todos los días a la oficina | BX8: Iguales que cuando iba todos los días a la oficina | BY8: Igual que cuando iba todos los días a la oficina | BZ8: Igual que cuando iba todos los días a la oficina | CA8: Igual que cuando iba todos los días a la oficina | CB8: Igual que cuando iba todos los días a la oficina | CC8: Igual que cuando iba todos los días a la oficina | CD8: Igual que cuando iba todos los días a la oficina | CE8: Igual que cuando iba todos los días a la oficina | CF8: Igual que cuando iba todos los días a la oficina | CG8: Igual que cuando iba todos los días a la oficina | CH8: Igual que cuando iba todos los días a la oficina | CI8: Igual que cuando iba todos los días a la oficina | CJ8: Igual que cuando iba todos los días a la oficina | CK8: Iguales que cuando iba todos los días a la oficina | CL8: Igual que cuando iba todos los días a la oficina | CM8: Igual que cuando iba todos los días a la oficina | CN8: de.escobarc1@uniandes.edu.co | CO8: <301 empleados | CP8: =IFERROR(VLOOKUP(H8,'Lista Lideres'!$A$1:$B$350,2,0),0) -> 1
A9: 45562.001 | B9: Colombia | C9: <35 años | D9: Masculino | E9: Postgrado | F9: 5-10 años | G9: Desarrollador de Software | H9: Tech Lead | I9: 301-500 empleados | J9: Fábrica de Software | K9: Local | L9: Casi Nunca | M9: Alto | N9: >5 días | O9: Ninguno | P9: Remota ( todos los días en casa) | Q9: Consensuada por las dos partes | R9: De acuerdo | S9: Igual que cuando iba todos los días a la oficina | T9: Igual que cuando iba todos los días a la oficina | U9: Igual que cuando iba todos los días a la oficina | V9: Iguales que cuando iba todos los días a la oficina | W9: Casi todas por videoconferencia | X9: Menor que cuando eran en la oficina | Y9: Mayor que cuando iba todos los días a la oficina | Z9: Igual que cuando iba todos los días a la oficina | AA9: Igual que cuando iba todos los días a la oficina | AB9: Igual que cuando iba todos los días a la oficina | AC9: Mucho Mejor que cuando iba todos los días a la oficina | AD9: Mejora mi desempeño en el trabajo | AE9: No afectan a mi productividad | AF9: Igual que cuando iba todos los días a la oficina | AG9: Menor que cuando iba todos los días a la oficina | AH9: Igual que cuando iba todos los días a la oficina | AI9: Igual que cuando iba todos los días a la oficina | AJ9: No trabajo con personas con un horario distinto al mío | AK9: Igual que cuando iba todos los días a la oficina | AL9: No tengo la información para contestar a la pregunta | AM9: Menos que cuando iba todos los días a la oficina | AN9: Igual que cuando iba todos los días a la oficina | AO9: Igual que cuando iba todos los días a la oficina | AP9: Igual que cuando iba todos los días a la oficina | AQ9: Iguales que cuando iba todos los días a la oficina | AR9: Igual que cuando iba todos los días a la oficina | AS9: Igual que cuando iba todos los días a la oficina | AT9: Menor que cuando iba todos los días a la oficina | AU9: Mayor que cuando iba todos los días a la oficina | AV9: Menor que cuando iba todos los días a la oficina | AW9: Menor que cuando iba todos los días a la oficina | AX9: Igual que cuando iba todos los días a la oficina | AY9: Mucho mayor que cuando iba todos los días a la oficina | AZ9: Mucho menores que cuando iba todos los días a la oficina | BA9: Igual que cuando iba todos los días a la oficina | BB9: No hay diferencias culturales en mi equipo | BC9: Igual que cuando iba todos los días a la oficina | BD9: Iguales que cuando iba todos los días a la oficina | BE9: No tengo que utilizar diferentes idiomas en mi trabajo | BF9: No trabajo con personas con distintos horarios | BG9: Igual que cuando iba todos los días a la oficina | BH9: Mucho menores que cuando iba todos los días a la oficina | BI9: Mucho mayor que cuando iba todos los días a la oficina | BJ9: Igual que cuando iba todos los días a la oficina | BK9: No tengo la información para contestar a la pregunta | BL9: Iguales que cuando iba todos los días a la oficina | BM9: Igual que cuando iba todos los días a la oficina | BN9: Mucho Mayor que cuando iba todos los días a la oficina | BO9: Mucho Mayor que cuando iba todos los días a la oficina | BP9: Mucho mayor que cuando iba todos los días a la oficina | BQ9: Mayor que cuando iba todos los días a la oficina | BR9: Igual que cuando iba todos los días a la oficina | BS9: Mayor que cuando iba todos los días a la oficina | BT9: Mucho Mayor que cuando iba todos los días a la oficina | BU9: Mucho Mayor que cuando iba todos los días a la oficina | BV9: Igual que cuando iba todos los días a la oficina | BW9: Igual que cuando iba todos los días a la oficina | BX9: Menores que cuando iba todos los días a la oficina | BY9: Igual que cuando iba todos los días a la oficina | BZ9: Mayor que cuando iba todos los días a la oficina | CA9: Igual que cuando iba todos los días a la oficina | CB9: Menor que cuando iba todos los días a la oficina | CC9: Igual que cuando iba todos los días a la oficina | CD9: Igual que cuando iba todos los días a la oficina | CE9: Mejor que cuando iba todos los días a la oficina | CF9: Igual que cuando iba todos los días a la oficina | CG9: Igual que cuando iba todos los días a la oficina | CH9: Igual que cuando iba todos los días a la oficina | CI9: Mucho Mayor que cuando iba todos los días a la oficina | CJ9: Mucho menor que cuando iba todos los días a la oficina | CK9: Iguales que cuando iba todos los días a la oficina | CL9: Igual que cuando iba todos los días a la oficina | CM9: Mucho mayor que cuando iba todos los días a la oficina | CN9: xavigonpa@gmail.com | CO9: 301+ empleados | CP9: =IFERROR(VLOOKUP(H9,'Lista Lideres'!$A$1:$B$350,2,0),0) -> 1
A10: 45572.954 | B10: Colombia | C10: <35 años | D10: Masculino | E10: Maestria | F10: 5-10 años | G10: Desarrollador de Software | H10: Software Designer | I10: >500 empleados. | J10: Fábrica de Software | K10: Multinacional | L10: Muy Frecuentemente | M10: Alto | N10: >5 días | O10: Ninguno | P10: Remota ( todos los días en casa) | Q10: Decidida por ti | R10: Totalmente de acuerdo | S10: Igual que cuando iba todos los días a la oficina | T10: Igual que cuando iba todos los días a la oficina | U10: Igual que cuando iba todos los días a la oficina | V10: Iguales que cuando iba todos los días a la oficina | W10: Todas por videoconferencia | X10: Mucho Mayor que cuando eran en la oficina | Y10: Mucho Mayor que cuando iba todos los días a la oficina | Z10: Mucho Mayor que cuando iba todos los días a la oficina | AA10: Mayor que cuando iba todos los días a la oficina | AB10: Mayor que cuando iba todos los días a la oficina | AC10: Mayor que cuando iba todos los días a la oficina | AD10: No me influye | AE10: Mejoran mucho mi productividad | AF10: Igual que cuando iba todos los días a la oficina | AG10: Mucho mayor que cuando iba todos los días a la oficina | AH10: Mucho menos que cuando iba todos los días a la oficina | AI10: Igual que cuando iba todos los días a la oficina | AJ10: Mucho menos que cuando iba todos los días a la oficina | AK10: Mucho menos que cuando iba todos los días a la oficina | AL10: Mucho más que cuando iba todos los días a la oficina | AM10: Menos que cuando iba todos los días a la oficina | AN10: Menos que cuando iba todos los días a la oficina | AO10: Menos que cuando iba todos los días a la oficina | AP10: Mucho mas que cuando iba todos los días a la oficina | AQ10: Mucho Mayores que cuando iba todos los días a la oficina | AR10: Mucho Mayor que cuando iba todos los días a la oficina | AS10: Mucho Mayor que cuando iba todos los días a la oficina | AT10: Mucho menor que cuando iba todos los días a la oficina | AU10: Mucho Mayor que cuando iba todos los días a la oficina | AV10: Mucho menor que cuando iba todos los días a la oficina | AW10: Mucho menor que cuando iba todos los días a la oficina | AX10: Mucho menor que cuando iba todos los días a la oficina | AY10: Mucho mayor que cuando iba todos los días a la oficina | AZ10: Mucho menores que cuando iba todos los días a la oficina | BA10: Mucho mayor que cuando iba todos los días a la oficina | BB10: No hay diferencias culturales en mi equipo | BC10: Mucho mayor que cuando iba todos los días a la oficina | BD10: Mucho menores que cuando iba todos los días a la oficina | BE10: Mucho menores que cuando iba todos los días a la oficina | BF10: Mucho menos que cuando iba todos los días a la oficina | BG10: Menor que cuando iba todos los días a la oficina | BH10: Menores que cuando iba todos los días a la oficina | BI10: Mucho mayor que cuando iba todos los días a la oficina | BJ10: Igual que cuando iba todos los días a la oficina | BK10: Menos que cuando iba todos los días a la oficina | BL10: Menores que cuando iba todos los días a la oficina | BM10: Igual que cuando iba todos los días a la oficina | BN10: Mucho Mayor que cuando iba todos los días a la oficina | BO10: Mucho Mayor que cuando iba todos los días a la oficina | BP10: Mucho mayor que cuando iba todos los días a la oficina | BQ10: Mucho Mayor que cuando iba todos los días a la oficina | BR10: Mucho Mayor que cuando iba todos los días a la oficina | BS10: Mucho Mayor que cuando iba todos los días a la oficina | BT10: Mucho Mayor que cuando iba todos los días a la oficina | BU10: Menor que cuando iba todos los días a la oficina | BV10: Menor que cuando iba todos los días a la oficina | BW10: Mucho mas que cuando iba todos los días a la oficina | BX10: Mucho Mayores que cuando iba todos los días a la oficina | BY10: Mucho Mayor que cuando iba todos los días a la oficina | BZ10: Mucho Mayor que cuando iba todos los días a la oficina | CA10: Mucho Mayor que cuando iba todos los días a la oficina | CB10: Menor que cuando iba todos los días a la oficina | CC10: Mucho Mayor que cuando iba todos los días a la oficina | CD10: Menor que cuando iba todos los días a la oficina | CE10: Mucho Mejor que cuando iba todos los días a la oficina | CF10: Mucho Mayor que cuando iba todos los días a la oficina | CG10: Mucho Mayor que cuando iba todos los días a la oficina | CH10: Mucho Mayor que cuando iba todos los días a la oficina | CI10: Mucho Mayor que cuando iba todos los días a la oficina | CJ10: Mucho Mayor que cuando iba todos los días a la oficina | CK10: Mucho Mayores que cuando iba todos los días a la oficina | CL10: Mucho Mayor que cuando iba todos los días a la oficina | CM10: Mucho mayor que cuando iba todos los días a la oficina | CO10: 301+ empleados | CP10: =IFERROR(VLOOKUP(H10,'Lista Lideres'!$A$1:$B$350,2,0),0) -> 0
A11: 45572.985 | B11: Colombia | C11: <35 años | D11: Femenino | E11: Universitario | F11: 5-10 años | G11: Desarrollador de software | H11: Desarrollador de software | I11: >500 empleados. | J11: Empresa que desarrolla software a medida partiendo desde cero | K11: Multinacional | L11: Muy Frecuentemente | M11: Alto | N11: >5 días | O11: Ninguno | P11: Remota ( todos los días en casa) | Q11: Consensuada por las dos partes | R11: Totalmente de acuerdo | S11: Igual que cuando iba todos los días a la oficina | T11: Igual que cuando iba todos los días a la oficina | U11: Igual que cuando iba todos los días a la oficina | V11: Diferentes que cuando iba todos los días a la oficina, ahora necesito menos horas para hacer lo mismo | W11: Todas por videoconferencia | X11: Menor que cuando eran en la oficina | Y11: Mucho Mayor que cuando iba todos los días a la oficina | Z11: No tengo la información para contestar a la pregunta | AA11: Mayor que cuando iba todos los días a la oficina | AB11: Mayor que cuando iba todos los días a la oficina | AC11: Igual que cuando iba todos los días a la oficina | AD11: Mejora mi desempeño en el trabajo | AE11: Mejoran mi productividad | AF11: Mayor que cuando iba todos los días a la oficina | AG11: No tengo la información para contestar a la pregunta | AH11: No tengo la información para contestar a la pregunta | AI11: Mucho menos que cuando iba todos los días a la oficina | AJ11: Igual que cuando iba todos los días a la oficina | AK11: Igual que cuando iba todos los días a la oficina | AL11: Igual que cuando iba todos los días a la oficina | AM11: Igual que cuando iba todos los días a la oficina | AN11: Igual que cuando iba todos los días a la oficina | AO11: Igual que cuando iba todos los días a la oficina | AP11: Igual que cuando iba todos los días a la oficina | AQ11: Mucho Mayores que cuando iba todos los días a la oficina | AR11: Igual que cuando iba todos los días a la oficina | AS11: Mayor que cuando iba todos los días a la oficina | AT11: Mucho menor que cuando iba todos los días a la oficina | AU11: Igual que cuando iba todos los días a la oficina | AV11: Menor que cuando iba todos los días a la oficina | AW11: Menor que cuando iba todos los días a la oficina | AX11: Mayor que cuando iba todos los días a la oficina | AY11: Mucho mayor que cuando iba todos los días a la oficina | AZ11: Iguales que cuando iba todos los días a la oficina | BA11: Igual que cuando iba todos los días a la oficina | BB11: Iguales que cuando iba todos los días a la oficina | BC11: Mucho mayor que cuando iba todos los días a la oficina | BD11: Menores que cuando iba todos los días a la oficina | BE11: Menores que cuando iba todos los días a la oficina | BF11: Mucho menos que cuando iba todos los días a la oficina | BG11: Igual que cuando iba todos los días a la oficina | BH11: Menores que cuando iba todos los días a la oficina | BI11: Mucho mayor que cuando iba todos los días a la oficina | BJ11: Mayor que cuando iba todos los días a la oficina | BK11: Menos que cuando iba todos los días a la oficina | BL11: Menores que cuando iba todos los días a la oficina | BM11: Igual que cuando iba todos los días a la oficina | BN11: Mucho Mayor que cuando iba todos los días a la oficina | BO11: Mucho Mayor que cuando iba todos los días a la oficina | BP11: Mucho mayor que cuando iba todos los días a la oficina | BQ11: Igual que cuando iba todos los días a la oficina | BR11: Igual que cuando iba todos los días a la oficina | BS11: Igual que cuando iba todos los días a la oficina | BT11: Mucho Mayor que cuando iba todos los días a la oficina | BU11: Mucho menor que cuando iba todos los días a la oficina | BV11: Mayor que cuando iba todos los días a la oficina | BW11: Igual que cuando iba todos los días a la oficina | BX11: Iguales que cuando iba todos los días a la oficina | BY11: Mucho Mayor que cuando iba todos los días a la oficina | BZ11: Mucho Mayor que cuando iba todos los días a la oficina | CA11: Igual que cuando iba todos los días a la oficina | CB11: Mucho menor que cuando iba todos los días a la oficina | CC11: Menor que cuando iba todos los días a la oficina | CD11: Mayor que cuando iba todos los días a la oficina | CE11: Mejor que cuando iba todos los días a la oficina | CF11: Mayor que cuando iba todos los días a la oficina | CG11: Menor que cuando iba todos los días a la oficina | CH11: Igual que cuando iba todos los días a la oficina | CI11: Mucho Mayor que cuando iba todos los días a la oficina | CJ11: Igual que cuando iba todos los días a la oficina | CK11: Iguales que cuando iba todos los días a la oficina | CL11: Igual que cuando iba todos los días a la oficina | CM11: Mucho mayor que cuando iba todos los días a la oficina | CO11: 301+ empleados | CP11: =IFERROR(VLOOKUP(H11,'Lista Lideres'!$A$1:$B$350,2,0),0) -> 0
A12: 45573.206 | B12: Colombia | C12: <35 años | D12: Masculino | E12: Profesional | F12: 5-10 años | G12: Desarrollador de software | H12: Desarrollador de software | I12: >500 empleados. | J12: Fábrica de Software | K12: Multinacional | L12: Frecuentemente | M12: Alto | N12: >5 días | O12: Ninguno | P12: Remota ( todos los días en casa) | Q12: Impuesta por la empresa | R12: De acuerdo | S12: Menor que cuando iba todos los días a la oficina | T12: Mucho menor que cuando iba todos los días a la oficina | U12: Menor que cuando iba todos los días a la oficina | V12: Diferentes que cuando iba todos los días a la oficina, ahora necesito menos horas para hacer lo mismo | W12: Todas por videoconferencia | X12: Menor que cuando eran en la oficina | Y12: Menor cuando iba todos los días a la oficina | Z12: Igual que cuando iba todos los días a la oficina | AA12: Igual que cuando iba todos los días a la oficina | AB12: Menor que cuando iba todos los días a la oficina | AC12: Mayor que cuando iba todos los días a la oficina | AD12: Mejora mucho mi desempeño en el trabajo | AE12: Mejoran mi productividad | AF12: Menor que cuando iba todos los días a la oficina | AG12: Menor que cuando iba todos los días a la oficina | AH12: Más que cuando iba todos los días a la oficina | AI12: Igual que cuando iba todos los días a la oficina | AJ12: Más que cuando iba todos los días a la oficina | AK12: Más que cuando iba todos los días a la oficina | AL12: Más que cuando iba todos los días a la oficina | AM12: Menos que cuando iba todos los días a la oficina | AN12: Menos que cuando iba todos los días a la oficina | AO12: Menos que cuando iba todos los días a la oficina | AP12: Menos que cuando iba todos los días a la oficina | AQ12: Mayores que cuando iba todos los días a la oficina | AR12: Igual que cuando iba todos los días a la oficina | AS12: Mayor que cuando iba todos los días a la oficina | AT12: Menor que cuando iba todos los días a la oficina | AU12: Mayor que cuando iba todos los días a la oficina | AV12: Menor que cuando iba todos los días a la oficina | AW12: Menor que cuando iba todos los días a la oficina | AX12: Menor que cuando iba todos los días a la oficina | AY12: Mayor que cuando iba todos los días a la oficina | AZ12: Menores que cuando iba todos los días a la oficina | BA12: Menor que cuando iba todos los días a la oficina | BB12: Iguales que cuando iba todos los días a la oficina | BC12: Igual que cuando iba todos los días a la oficina | BD12: Iguales que cuando iba todos los días a la oficina | BE12: Mayores que cuando iba todos los días a la oficina | BF12: Menos que cuando iba todos los días a la oficina | BG12: Menor que cuando iba todos los días a la oficina | BH12: Menores que cuando iba todos los días a la oficina | BI12: Mayor que cuando iba todos los días a la oficina | BJ12: Igual que cuando iba todos los días a la oficina | BK12: Menos que cuando iba todos los días a la oficina | BL12: Menores que cuando iba todos los días a la oficina | BM12: Mejor que cuando iba todos los días a la oficina | BN12: Mayor que cuando iba todos los días a la oficina | BO12: Mucho menor que cuando iba todos los días a la oficina | BP12: Mayor que cuando iba todos los días a la oficina | BQ12: Menor que cuando iba todos los días a la oficina | BR12: Mayor que cuando iba todos los días a la oficina | BS12: Mayor que cuando iba todos los días a la oficina | BT12: Mayor que cuando iba todos los días a la oficina | BU12: Mayor que cuando iba todos los días a la oficina | BV12: Menor que cuando iba todos los días a la oficina | BW12: Mas que cuando iba todos los días a la oficina | BX12: Menores que cuando iba todos los días a la oficina | BY12: Mayor que cuando iba todos los días a la oficina | BZ12: Mayor que cuando iba todos los días a la oficina | CA12: Mayor que cuando iba todos los días a la oficina | CB12: Mayor que cuando iba todos los días a la oficina | CC12: Menor que cuando iba todos los días a la oficina | CD12: Mucho menor que cuando iba todos los días a la oficina | CE12: Mejor que cuando iba todos los días a la oficina | CF12: Mayor que cuando iba todos los días a la oficina | CG12: Mucho menor que cuando iba todos los días a la oficina | CH12: Mayor que cuando iba todos los días a la oficina | CI12: Mayor que cuando iba todos los días a la oficina | CJ12: Menor que cuando iba todos los días a la oficina | CK12: Menores que cuando iba todos los días a la oficina | CL12: Mayor que cuando iba todos los días a la oficina | CM12: Mayor que cuando iba todos los días a la oficina | CO12: 301+ empleados | CP12: =IFERROR(VLOOKUP(H12,'Lista Lideres'!$A$1:$B$350,2,0),0) -> 0
