Workbook

Sheet Datos
A1: Marca temporal | B1: ¿En qué país resides? | C1: Tu edad está dentro del rango: | D1: ¿Tu género es? | E1: Indica tu nivel de estudios: | F1: Actualmente trabajas: | G1: En el caso de trabajar para una empresa, indica en qué país está su sede principal: | H1: Indica los años de experiencia trabajando en empresas de desarrollo de software: | I1: Indica los años que has trabajado de forma presencial | J1: Por favor indica el puesto que ocupabas cuando trabajabas presencialmente en la empresa: | K1: Por favor indica el puesto que ocupas actualmente en la empresa: | L1: Nombre de la compañía (opcional): | M1: Tamaño de la compañía | N1: Tipo de empresa: | O1: Tu empresa es: | P1: ¿En tu trabajo te comunicas con personas de distintos países? | Q1: NIVEL HOMEOFFICE | R1: ¿Cuántos días a la semana trabajas desde casa actualmente? | S1: ¿Cuántos días a la semana vas a la oficina actualmente? | T1: ¿Si tu contrato no te obliga a ir a la oficina ningún día a la semana indica en qué ocasiones se te ha solicitado ir a la oficina? | U1: En el caso de que tu empresa te obligue a ir a la oficina algún día a la semana, indica en qué ocasiones has tenido que asistir: | V1: En el caso de que tu empresa te recomiende a ir a la oficina algún día a la semana, indica en qué ocasiones se te ha solicitado: | W1: Si te ofrece tu empresa alguna clase de recompensa por ir a la oficina (parking gratuito, tickets para comidas, mejora en las instalaciones.), indica cuáles son: | X1: ¿Qué modalidad de trabajo prefieres? | Y1: La modalidad que actualmente tienes fue: | Z1: Trabajo la misma cantidad de horas que cuando trabajaba todos los días en la oficina | AA1: El intercambio de conocimiento con mis compañeros de proyecto es ahora: | AB1: La comunicación en general con mis compañeros de proyecto es ahora | AC1: La comunicación con mis jefes es ahora | AD1: Tus horarios de trabajo ahora son: | AE1: Mis reuniones ahora son: | AF1: El cansancio después de una reunión online es ahora: | AG1: Siento que mi rendimiento ahora es: | AH1: Siento que la productividad de mi equipo es: | AI1: Siento que la capacidad de mi equipo para cumplir hitos es: | AJ1: Siento que mi concentración cuando estoy trabajando es: | AK1: Siento que la velocidad de mi conexión a Internet es | AL1: Siento que la eficiencia de la conexión a Internet me influye: | AM1: Las herramientas de comunicación (Teams, Zoom, Slack,...) utilizadas por mi empresa, desde casa: | AN1: Siento que la facilidad para compartir conocimiento ahora es: | AO1: Siento que el impacto de la rotación de personal en la empresa ahora es: | AP1: Siento que la falta de compromiso por parte de los empleados, afecta a la productividad: | AQ1: Siento que el hecho de trabajar con personas de distintas culturas afecta a la productividad: | AR1: Siento que el hecho de trabajar con personas que tienen otros horarios afecta a la productividad | AS1: Siento que el hecho de trabajar con personas que se encuentran geográficamente distribuidas afecta a la productividad: | AT1: Siento que la falta de confianza entre los miembros del equipo afecta la productividad | AU1: Siento que la falta de colaboración entre los miembros del equipo afecta la productividad: | AV1: Siento que la falta de relaciones personales entre los miembros del equipo afecta la productividad: | AW1: Siento que la falta de cohesión y de espíritu de grupo afecta la productividad | AX1: Siento que los problemas de liderazgo afectan la productividad | AY1: Siento que el nivel de la definición de los requisitos de software y su calidad son ahora: | AZ1: Siento que el control de los cambios de los requisitos es ahora: | BA1: Siento que la cantidad de personal cualificado en la empresa es ahora: | BB1: Siento que mi nivel de estrés es: | BC1: Siento que mi nivel de confianza para enfrentarme a los retos del trabajo es: | BD1: Siento que mis reacciones de enojo o molestia ahora son: | BE1: Siento que mi nivel de frustración con relación al trabajo es: | BF1: Siento que el nivel de presión por terminar las tareas ahora es: | BG1: Siento que la flexibilidad de mi trabajo ahora es: | BH1: Siento que los problemas tecnológicos ahora son: | BI1: Siento que la facilidad para trabajar en equipos distribuidos es: | BJ1: Siento que los problemas que aparecen por las diferencias culturales ahora son: | BK1: Siento que la aplicación de metodología ágiles ahora es: | BL1: Siento que los problemas de comunicación ahora son: | BM1: Siento que los problemas por usar distintos idiomas ahora son: | BN1: Siento que el hecho de trabajar con personas que tienen otros horarios afecta a mi estrés: | BO1: Siento que la generación de confianza entre los miembros del equipo ahora es: | BP1: Siento que las interrupciones externas ahora son: | BQ1: Siento que ahora mi manejo del tiempo en general es: | BR1: Siento que la falta de compañerismo ahora es: | BS1: Siento que los problemas de coordinación afectan a mi estrés: | BT1: Siento que los problemas vinculados con la gestión del proyecto ahora son: | BU1: Siento que la asignación de tareas entre los miembros del equipo ahora es: | BV1: Siento que mi nivel de motivación en el trabajo es: | BW1: Mi concentración ahora cuando estoy trabajando es: | BX1: Mi comodidad ahora cuando estoy trabajando es: | BY1: Mi seguridad/ confianza a la hora de preguntar a un compañero ahora es: | BZ1: Mi confianza para hacer preguntas a un superior ahora es: | CA1: Mi habilidad para resolver problemas ahora es: | CB1: En términos de disfrute en el trabajo siento que ahora es: | CC1: Siento que el nivel de interés hacia mi trabajo ahora es: | CD1: Siento que la falta de conocimiento sobre el rol de cada miembro del equipo ahora es: | CE1: Siento que mi empresa me aprecia: | CF1: Siento que las acciones de motivación de personal de mi empresa son: | CG1: Siento que la calidad del desarrollo de software es ahora: | CH1: Siento que el equilibrio vida personal - trabajo es ahora: | CI1: Siento que ahora la retroalimentación que recibo por parte de mis compañeros y superiores es: | CJ1: Siento que mi nivel de aburrimiento en el trabajo es ahora: | CK1: Siento que mi nivel de atención a cada individuo es ahora: | CL1: Siento que mi miedo a perder el trabajo es ahora: | CM1: Siento que el ambiente de trabajo ahora es: | CN1: Siento que mi nivel de influencia en mi equipo de trabajo es ahora: | CO1: Siento que la facilidad para desarrollar relaciones personales entre los compañeros de trabajo es ahora | CP1: Siento que la participación de los miembros en los proyectos de mi equipo es ahora: | CQ1: Siento que el nivel de autonomía en el trabajo es ahora | CR1: Siento que el nivel de relaciones conflictivas entre compañeros es ahora: | CS1: Siento que los problemas relacionados con el liderazgo compartido son ahora: | CT1: El sentimiento de pertenencia a mi empresa es ahora | CU1: Siento que mi creatividad es: | CV1: Correo electrónico para recibir resultados (opcional) | CW1: Tam_Empresa | CX1: Lead | CY1: =_xlfn.TEXTJOIN(",",FALSE,A1:CX1) -> Marca temporal,¿En qué país resides?,Tu edad está dentro del rango:,¿Tu género es?,Indica tu nivel de estudios:,Actualmente trabajas:,En el caso de trabajar para una empresa, indica en qué país está su sede principal:,Indica los años de experiencia trabajando en empresas de desarrollo de software:,Indica los años que has trabajado de forma presencial,Por favor indica el puesto que ocupabas cuando trabajabas presencialmente en la empresa:,Por favor indica el puesto que ocupas actualmente en la empresa:,Nombre de la compañía (opcional):,Tamaño de la compañía,Tipo de empresa:,Tu empresa es:,¿En tu trabajo te comunicas con personas de distintos países?,NIVEL HOMEOFFICE,¿Cuántos días a la semana trabajas desde casa actualmente?,¿Cuántos días a la semana vas a la oficina actualmente?,¿Si tu contrato no te obliga a ir a la oficina ningún día a la semana indica en qué ocasiones se te ha solicitado ir a la oficina?,En el caso de que tu empresa te obligue a ir a la oficina algún día a la semana, indica en qué ocasiones has tenido que asistir:,En el caso de que tu empresa te recomiende a ir a la oficina algún día a la semana, indica en qué ocasiones se te ha solicitado:,Si te ofrece tu empresa alguna clase de recompensa por ir a la oficina (parking gratuito, tickets para comidas, mejora en las instalaciones.), indica cuáles son:,¿Qué modalidad de trabajo prefieres?,La modalidad que actualmente tienes fue:,Trabajo la misma cantidad de horas que cuando trabajaba todos los días en la oficina,El intercambio de conocimiento con mis compañeros de proyecto es ahora:,La comunicación en general con mis compañeros de proyecto es ahora,La comunicación con mis jefes es ahora,Tus horarios de trabajo ahora son:,Mis reuniones ahora son:,El cansancio después de una reunión online es ahora:,Siento que mi rendimiento ahora es:,Siento que la productividad de mi equipo es:,Siento que la capacidad de mi equipo para cumplir hitos es:,Siento que mi concentración cuando estoy trabajando es:,Siento que la velocidad de mi conexión a Internet es,Siento que la eficiencia de la conexión a Internet me influye:,Las herramientas de comunicación (Teams, Zoom, Slack,...) utilizadas por mi empresa, desde casa:,Siento que la facilidad para compartir conocimiento ahora es: ,Siento que el impacto de la rotación de personal en la empresa ahora es: ,Siento que la falta de compromiso por parte de los empleados, afecta a la productividad:,Siento que el hecho de trabajar con personas de distintas culturas afecta a la productividad:,Siento que el hecho de trabajar con personas que tienen otros horarios afecta a la productividad,Siento que el hecho de trabajar con personas que se encuentran geográficamente distribuidas afecta a la productividad:,Siento que la falta de confianza entre los miembros del equipo afecta la productividad,Siento que la falta de colaboración entre los miembros del equipo afecta la productividad:,Siento que la falta de relaciones personales entre los miembros del equipo afecta la productividad:,Siento que la falta de cohesión y de espíritu de grupo afecta la productividad,Siento que los problemas de liderazgo afectan la productividad,Siento que el nivel de la definición de los requisitos de software y su calidad son ahora:,Siento que el control de los cambios de los requisitos es ahora:,Siento que la cantidad de personal cualificado en la empresa es ahora:,Siento que mi nivel de estrés es:,Siento que mi nivel de confianza para enfrentarme a los retos del trabajo es: ,Siento que mis reacciones de enojo o molestia ahora son:,Siento que mi nivel de frustración con relación al trabajo es: ,Siento que el nivel de presión por terminar las tareas ahora es:,Siento que la flexibilidad de mi trabajo ahora es:,Siento que los problemas tecnológicos ahora son:,Siento que la facilidad para trabajar en equipos distribuidos es:,Siento que los problemas que aparecen por las diferencias culturales ahora son:,Siento que la aplicación de metodología ágiles ahora es:,Siento que los problemas de comunicación ahora son:,Siento que los problemas por usar distintos idiomas ahora son:,Siento que el hecho de trabajar con personas que tienen otros horarios afecta a mi estrés:,Siento que la generación de confianza entre los miembros del equipo ahora es:,Siento que las interrupciones externas ahora son:,Siento que ahora mi manejo del tiempo en general es:,Siento que la falta de compañerismo ahora es:,Siento que los problemas de coordinación afectan a mi estrés:,Siento que los problemas vinculados con la gestión del proyecto ahora son:,Siento que la asignación de tareas entre los miembros del equipo ahora es:,Siento que mi nivel de motivación en el trabajo es:,Mi concentración ahora cuando estoy trabajando es:,Mi comodidad ahora cuando estoy trabajando es:,Mi seguridad/ confianza a la hora de preguntar a un compañero ahora es:,Mi confianza para hacer preguntas a un superior ahora es:,Mi habilidad para resolver problemas ahora es:,En términos de disfrute en el trabajo siento que ahora es:,Siento que el nivel de interés hacia mi trabajo ahora es: ,Siento que la falta de conocimiento sobre el rol de cada miembro del equipo ahora es:,Siento que mi empresa me aprecia:,Siento que las acciones de motivación de personal de mi empresa son:,Siento que la calidad del desarrollo de software es ahora:,Siento que el equilibrio vida personal - trabajo es ahora:,Siento que ahora la retroalimentación que recibo por parte de mis compañeros y superiores es:,Siento que mi nivel de aburrimiento en el trabajo es ahora:,Siento que mi nivel de atención a cada individuo es ahora:,Siento que mi miedo a perder el trabajo es ahora:,Siento que el ambiente de trabajo ahora es:,Siento que mi nivel de influencia en mi equipo de trabajo es ahora:,Siento que la facilidad para desarrollar relaciones personales entre los compañeros de trabajo es ahora,Siento que la participación de los miembros en los proyectos de mi equipo es ahora:,Siento que el nivel de autonomía en el trabajo es ahora,Siento que el nivel de relaciones conflictivas entre compañeros es ahora:,Siento que los problemas relacionados con el liderazgo compartido son ahora:,El sentimiento de pertenencia a mi empresa es ahora,Siento que mi creatividad es:,Correo electrónico para recibir resultados (opcional),Tam_Empresa,Lead
A2: 45594.111 | B2: Argentina | C2: <35 años | D2: Masculino | E2: Universitarios completo | F2: Como empleado de una empresa | G2: Argentina | H2: 5-10 años | I2: <5 años | J2: Desarrollador de Software | K2: Líder Técnico | M2: >500 empleados. | N2: Empresa que desarrolla software a medida partiendo desde cero | O2: Multinacional | P2: Muy Frecuentemente | Q2: Alto | R2: >5 días | S2: Ninguno | T2: Se me solicita ir a una sede una vez cada 3 meses aproximadamente | W2: Parking gratuito, descuentos en accesorios electrónicos de uso personal si se adquiere en la sede | X2: Remota ( todos los días en casa) | Y2: Consensuada por las dos partes | Z2: En desacuerdo | AA2: Igual que cuando iba todos los días a la oficina | AB2: Igual que cuando iba todos los días a la oficina | AC2: Mayor que cuando iba todos los días a la oficina | AD2: Diferentes que cuando iba todos los días a la oficina, ahora necesito menos horas para hacer lo mismo | AE2: Todas por videoconferencia | AF2: Igual que cuando eran en la oficina | AG2: Mayor que cuando iba todos los días a la oficina | AH2: Mayor que cuando iba todos los días a la oficina | AI2: Mayor que cuando iba todos los días a la oficina | AJ2: Mucho Mayor que cuando iba todos los días a la oficina | AK2: Mucho Mejor que cuando iba todos los días a la oficina | AL2: Mejora mucho mi desempeño en el trabajo | AM2: Mejoran mi productividad | AN2: Menor que cuando iba todos los días a la oficina | AO2: Mucho mayor que cuando iba todos los días a la oficina | AP2: Igual que cuando iba todos los días a la oficina | AQ2: Igual que cuando iba todos los días a la oficina | AR2: Mucho menos que cuando iba todos los días a la oficina | AS2: Mucho menos que cuando iba todos los días a la oficina | AT2: Más que cuando iba todos los días a la oficina | AU2: Igual que cuando iba todos los días a la oficina | AV2: Mas que cuando iba todos los días a la oficina | AW2: Igual que cuando iba todos los días a la oficina | AX2: Mas que cuando iba todos los días a la oficina | AY2: Mayores que cuando iba todos los días a la oficina | AZ2: Mucho Mayor que cuando iba todos los días a la oficina | BA2: Mucho Mayor que cuando iba todos los días a la oficina | BB2: Igual que cuando iba todos los días a la oficina | BC2: Mayor que cuando iba todos los días a la oficina | BD2: Menor que cuando iba todos los días a la oficina | BE2: Menor que cuando iba todos los días a la oficina | BF2: Mayor que cuando iba todos los días a la oficina | BG2: Mucho mayor que cuando iba todos los días a la oficina | BH2: Menores que cuando iba todos los días a la oficina | BI2: Mucho mayor que cuando iba todos los días a la oficina | BJ2: Iguales que cuando iba todos los días a la oficina | BK2: Mucho mayor que cuando iba todos los días a la oficina | BL2: Menores que cuando iba todos los días a la oficina | BM2: Menores que cuando iba todos los días a la oficina | BN2: Igual que cuando iba todos los días a la oficina | BO2: Menor que cuando iba todos los días a la oficina | BP2: Mayores que cuando iba todos los días a la oficina | BQ2: Mucho mayor que cuando iba todos los días a la oficina | BR2: Menor que cuando iba todos los días a la oficina | BS2: Igual que cuando iba todos los días a la oficina | BT2: Iguales que cuando iba todos los días a la oficina | BU2: Mejor que cuando iba todos los días a la oficina | BV2: Mucho Mayor que cuando iba todos los días a la oficina | BW2: Mayor que cuando iba todos los días a la oficina | BX2: Mayor que cuando iba todos los días a la oficina | BY2: Menor que cuando iba todos los días a la oficina | BZ2: Mayor que cuando iba todos los días a la oficina | CA2: Igual que cuando iba todos los días a la oficina | CB2: Mucho Mayor que cuando iba todos los días a la oficina | CC2: Igual que cuando iba todos los días a la oficina | CD2: Mayor que cuando iba todos los días a la oficina | CE2: Menos que cuando iba todos los días a la oficina | CF2: Iguales que cuando iba todos los días a la oficina | CG2: Mayor que cuando iba todos los días a la oficina | CH2: Mucho Mayor que cuando iba todos los días a la oficina | CI2: Mayor que cuando iba todos los días a la oficina | CJ2: Menor que cuando iba todos los días a la oficina | CK2: Mayor que cuando iba todos los días a la oficina | CL2: Mayor que cuando iba todos los días a la oficina | CM2: Igual que cuando iba todos los días a la oficina | CN2: Menor que cuando iba todos los días a la oficina | CO2: Menor que cuando iba todos los días a la oficina | CP2: Mayor que cuando iba todos los días a la oficina | CQ2: Mucho Mayor que cuando iba todos los días a la oficina | CR2: Mucho menor que cuando iba todos los días a la oficina | CS2: Menores que cuando iba todos los días a la oficina | CT2: Igual que cuando iba todos los días a la oficina | CU2: Igual que cuando iba todos los días a la oficina | CV2: juan.delafuente@fi.uncoma.edu.ar | CW2: 301+ empleados | CX2: =VLOOKUP(K2,Sheet2!$A$2:$B$58,2,0) -> 0 | CY2: =_xlfn.TEXTJOIN(",",FALSE,A2:CX2) -> 45594,1107893982,Argentina,<35 años,Masculino,Universitarios completo,Como empleado de una empresa,Argentina,5-10 años,<5 años,Desarrollador de Software,Líder Técnico ,,>500 empleados.,Empresa que desarrolla software a medida partiendo desde cero,Multinacional,Muy Frecuentemente,Alto,>5 días,Ninguno,Se me solicita ir a una sede una vez cada 3 meses aproximadamente,,,Parking gratuito, descuentos en accesorios electrónicos de uso personal si se adquiere en la sede,Remota ( todos los días en casa),Consensuada por las dos partes,En desacuerdo,Igual que cuando iba todos los días a la oficina,Igual que cuando iba todos los días a la oficina,Mayor que cuando iba todos los días a la oficina,Diferentes que cuando iba todos los días a la oficina, ahora necesito menos horas para hacer lo mismo,Todas por videoconferencia,Igual que cuando eran en la oficina,Mayor que cuando iba todos los días a la oficina,Mayor que cuando iba todos los días a la oficina,Mayor que cuando iba todos los días a la oficina,Mucho Mayor que cuando iba todos los días a la oficina,Mucho Mejor que cuando iba todos los días a la oficina,Mejora mucho mi desempeño en el trabajo,Mejoran mi productividad,Menor que cuando iba todos los días a la oficina,Mucho mayor que cuando iba todos los días a la oficina,Igual que cuando iba todos los días a la oficina,Igual que cuando iba todos los días a la oficina,Mucho menos que cuando iba todos los días a la oficina,Mucho menos que cuando iba todos los días a la oficina,Más que cuando iba todos los días a la oficina,Igual que cuando iba todos los días a la oficina,Mas que cuando iba todos los días a la oficina,Igual que cuando iba todos los días a la oficina,Mas que cuando iba todos los días a la oficina,Mayores que cuando iba todos los días a la oficina,Mucho Mayor que cuando iba todos los días a la oficina,Mucho Mayor que cuando iba todos los días a la oficina,Igual que cuando iba todos los días a la oficina,Mayor que cuando iba todos los días a la oficina,Menor que cuando iba todos los días a la oficina,Menor que cuando iba todos los días a la oficina,Mayor que cuando iba todos los días a la oficina,Mucho mayor que cuando iba todos los días a la oficina,Menores que cuando iba todos los días a la oficina,Mucho mayor que cuando iba todos los días a la oficina,Iguales que cuando iba todos los días a la oficina,Mucho mayor que cuando iba todos los días a la oficina,Menores que cuando iba todos los días a la oficina,Menores que cuando iba todos los días a la oficina,Igual que cuando iba todos los días a la oficina,Menor que cuando iba todos los días a la oficina,Mayores que cuando iba todos los días a la oficina,Mucho mayor que cuando iba todos los días a la oficina,Menor que cuando iba todos los días a la oficina,Igual que cuando iba todos los días a la oficina,Iguales que cuando iba todos los días a la oficina,Mejor que cuando iba todos los días a la oficina,Mucho Mayor que cuando iba todos los días a la oficina,Mayor que cuando iba todos los días a la oficina,Mayor que cuando iba todos los días a la oficina,Menor que cuando iba todos los días a la oficina,Mayor que cuando iba todos los días a la oficina,Igual que cuando iba todos los días a la oficina,Mucho Mayor que cuando iba todos los días a la oficina,Igual que cuando iba todos los días a la oficina,Mayor que cuando iba todos los días a la oficina,Menos que cuando iba todos los días a la oficina,Iguales que cuando iba todos los días a la oficina,Mayor que cuando iba todos los días a la oficina,Mucho Mayor que cuando iba todos los días a la oficina,Mayor que cuando iba todos los días a la oficina,Menor que cuando iba todos los días a la oficina,Mayor que cuando iba todos los días a la oficina,Mayor que cuando iba todos los días a la oficina,Igual que cuando iba todos los días a la oficina,Menor que cuando iba todos los días a la oficina,Menor que cuando iba todos los días a la oficina,Mayor que cuando iba todos los días a la oficina,Mucho Mayor que cuando iba todos los días a la oficina,Mucho menor que cuando iba todos los días a la oficina,Menores que cuando iba todos los días a la oficina,Igual que cuando iba todos los días a la oficina,Igual que cuando iba todos los días a la oficina,juan.delafuente@fi.uncoma.edu.ar,301+ empleados,0
A3: 45572.098 | B3: Argentina | C3: <35 años | D3: Femenino | E3: universitario | F3: De ambas formas | G3: Argentina | H3: 21-30 años | I3: 5-10 años | J3: Referente IT | K3: COO | M3: <50 empleados | N3: Empresa que desarrolla software a medida partiendo desde cero | O3: Multinacional | P3: Casi Nunca | Q3: Alto | R3: >5 días | S3: Ninguno | T3: Encuentros del equipo, reuniones gerenciales o con cliente | V3: Reuniones de equipo, lo deja a discreciónd el equipo | X3: Remota ( todos los días en casa) | Y3: Decidida por ti | Z3: En desacuerdo | AA3: Mayor que cuando iba todos los días a la oficina | AB3: Mayor que cuando iba todos los días a la oficina | AC3: Mayor que cuando iba todos los días a la oficina | AD3: Diferentes que cuando iba todos los días a la oficina, ahora necesito menos horas para hacer lo mismo | AE3: Casi todas por videoconferencia | AF3: Menor que cuando eran en la oficina | AG3: Mayor que cuando iba todos los días a la oficina | AH3: Mucho Mayor que cuando iba todos los días a la oficina | AI3: Mucho Mayor que cuando iba todos los días a la oficina | AJ3: Mayor que cuando iba todos los días a la oficina | AK3: Mucho Mejor que cuando iba todos los días a la oficina | AL3: Mejora mucho mi desempeño en el trabajo | AM3: No afectan a mi productividad | AN3: Igual que cuando iba todos los días a la oficina | AO3: Igual que cuando iba todos los días a la oficina | AP3: Igual que cuando iba todos los días a la oficina | AQ3: No trabajo con personas de distintas culturas | AR3: Mucho menos que cuando iba todos los días a la oficina | AS3: Mucho menos que cuando iba todos los días a la oficina | AT3: Igual que cuando iba todos los días a la oficina | AU3: Igual que cuando iba todos los días a la oficina | AV3: Igual que cuando iba todos los días a la oficina | AW3: Igual que cuando iba todos los días a la oficina | AX3: Igual que cuando iba todos los días a la oficina | AY3: Menores que cuando iba todos los días a la oficina | AZ3: Igual que cuando iba todos los días a la oficina | BA3: Igual que cuando iba todos los días a la oficina | BB3: Mucho menor que cuando iba todos los días a la oficina | BC3: Igual que cuando iba todos los días a la oficina | BD3: Igual que cuando iba todos los días a la oficina | BE3: Igual que cuando iba todos los días a la oficina | BF3: Igual que cuando iba todos los días a la oficina | BG3: Mucho mayor que cuando iba todos los días a la oficina | BH3: Mucho menores que cuando iba todos los días a la oficina | BI3: Mucho menor que cuando iba todos los días a la oficina | BJ3: No hay diferencias culturales en mi equipo | BK3: Mayor que cuando iba todos los días a la oficina | BL3: Iguales que cuando iba todos los días a la oficina | BM3: No tengo que utilizar diferentes idiomas en mi trabajo | BN3: Menos que cuando iba todos los días a la oficina | BO3: Igual que cuando iba todos los días a la oficina | BP3: Mucho menores que cuando iba todos los días a la oficina | BQ3: Mucho mayor que cuando iba todos los días a la oficina | BR3: Menor que cuando iba todos los días a la oficina | BS3: Menos que cuando iba todos los días a la oficina | BT3: Menores que cuando iba todos los días a la oficina | BU3: Igual que cuando iba todos los días a la oficina | BV3: Mayor que cuando iba todos los días a la oficina | BW3: Mayor que cuando iba todos los días a la oficina | BX3: Mayor que cuando iba todos los días a la oficina | BY3: Igual que cuando iba todos los días a la oficina | BZ3: Igual que cuando iba todos los días a la oficina | CA3: Igual que cuando iba todos los días a la oficina | CB3: Mayor que cuando iba todos los días a la oficina | CC3: Igual que cuando iba todos los días a la oficina | CD3: Igual que cuando iba todos los días a la oficina | CE3: Menos que cuando iba todos los días a la oficina | CF3: Iguales que cuando iba todos los días a la oficina | CG3: Mayor que cuando iba todos los días a la oficina | CH3: Mucho Mayor que cuando iba todos los días a la oficina | CI3: Mayor que cuando iba todos los días a la oficina | CJ3: Menor que cuando iba todos los días a la oficina | CK3: Menor que cuando iba todos los días a la oficina | CL3: Menor que cuando iba todos los días a la oficina | CM3: Mejor que cuando iba todos los días a la oficina | CN3: Mayor que cuando iba todos los días a la oficina | CO3: Igual que cuando iba todos los días a la oficina | CP3: Mayor que cuando iba todos los días a la oficina | CQ3: Mayor que cuando iba todos los días a la oficina | CR3: Menor que cuando iba todos los días a la oficina | CS3: Menores que cuando iba todos los días a la oficina | CT3: Menor que cuando iba todos los días a la oficina | CU3: Mayor que cuando iba todos los días a la oficina | CV3: baeza.natalia@gmail.com | CW3: <301 empleados | CX3: =VLOOKUP(K3,Sheet2!$A$2:$B$58,2,0) -> 1 | CY3: =_xlfn.TEXTJOIN(",",FALSE,A3:CX3) -> 45572,0978002431,Argentina,<35 años,Femenino,universitario,De ambas formas,Argentina,21-30 años,5-10 años,Referente IT,COO,,<50 empleados,Empresa que desarrolla software a medida partiendo desde cero,Multinacional,Casi Nunca,Alto,>5 días,Ninguno,Encuentros del equipo, reuniones gerenciales o con cliente,,Reuniones de equipo, lo deja a discreciónd el equipo,,Remota ( todos los días en casa),Decidida por ti,En desacuerdo,Mayor que cuando iba todos los días a la oficina,Mayor que cuando iba todos los días a la oficina,Mayor que cuando iba todos los días a la oficina,Diferentes que cuando iba todos los días a la oficina, ahora necesito menos horas para hacer lo mismo,Casi todas por videoconferencia,Menor que cuando eran en la oficina,Mayor que cuando iba todos los días a la oficina,Mucho Mayor que cuando iba todos los días a la oficina,Mucho Mayor que cuando iba todos los días a la oficina,Mayor que cuando iba todos los días a la oficina,Mucho Mejor que cuando iba todos los días a la oficina,Mejora mucho mi desempeño en el trabajo,No afectan a mi productividad,Igual que cuando iba todos los días a la oficina,Igual que cuando iba todos los días a la oficina,Igual que cuando iba todos los días a la oficina,No trabajo con personas de distintas culturas,Mucho menos que cuando iba todos los días a la oficina,Mucho menos que cuando iba todos los días a la oficina,Igual que cuando iba todos los días a la oficina,Igual que cuando iba todos los días a la oficina,Igual que cuando iba todos los días a la oficina,Igual que cuando iba todos los días a la oficina,Igual que cuando iba todos los días a la oficina,Menores que cuando iba todos los días a la oficina,Igual que cuando iba todos los días a la oficina,Igual que cuando iba todos los días a la oficina,Mucho menor que cuando iba todos los días a la oficina,Igual que cuando iba todos los días a la oficina,Igual que cuando iba todos los días a la oficina,Igual que cuando iba todos los días a la oficina,Igual que cuando iba todos los días a la oficina,Mucho mayor que cuando iba todos los días a la oficina,Mucho menores que cuando iba todos los días a la oficina,Mucho menor que cuando iba todos los días a la oficina,No hay diferencias culturales en mi equipo,Mayor que cuando iba todos los días a la oficina,Iguales que cuando iba todos los días a la oficina,No tengo que utilizar diferentes idiomas en mi trabajo,Menos que cuando iba todos los días a la oficina,Igual que cuando iba todos los días a la oficina,Mucho menores que cuando iba todos los días a la oficina,Mucho mayor que cuando iba todos los días a la oficina,Menor que cuando iba todos los días a la oficina,Menos que cuando iba todos los días a la oficina,Menores que cuando iba todos los días a la oficina,Igual que cuando iba todos los días a la oficina,Mayor que cuando iba todos los días a la oficina,Mayor que cuando iba todos los días a la oficina,Mayor que cuando iba todos los días a la oficina,Igual que cuando iba todos los días a la oficina,Igual que cuando iba todos los días a la oficina,Igual que cuando iba todos los días a la oficina,Mayor que cuando iba todos los días a la oficina,Igual que cuando iba todos los días a la oficina,Igual que cuando iba todos los días a la oficina,Menos que cuando iba todos los días a la oficina,Iguales que cuando iba todos los días a la oficina,Mayor que cuando iba todos los días a la oficina,Mucho Mayor que cuando iba todos los días a la oficina,Mayor que cuando iba todos los días a la oficina,Menor que cuando iba todos los días a la oficina,Menor que cuando iba todos los días a la oficina,Menor que cuando iba todos los días a la oficina,Mejor que cuando iba todos los días a la oficina,Mayor que cuando iba todos los días a la oficina,Igual que cuando iba todos los días a la oficina,Mayor que cuando iba todos los días a la oficina,Mayor que cuando iba todos los días a la oficina,Menor que cuando iba todos los días a la oficina,Menores que cuando iba todos los días a la oficina,Menor que cuando iba todos los días a la oficina,Mayor que cuando iba todos los días a la oficina,baeza.natalia@gmail.com,<301 empleados,1
A4: 45573.063 | B4: Colombia | C4: <35 años | D4: Masculino | E4: Profesional | F4: Como empleado de una empresa | G4: Bogotá | H4: 5-10 años | I4: 5-10 años | J4: Desarollador junior | K4: Líder técnico de desarrollo | L4: Lulo bank | M4: 151-300 empleados | N4: Empresa que desarrolla software a medida partiendo desde cero | O4: Local | P4: Casi Nunca | Q4: Alto | R4: >5 días | S4: Ninguno | T4: A integraciones de trabajo | X4: Remota ( todos los días en casa) | Y4: Impuesta por la empresa | Z4: Totalmente en desacuerdo | AA4: Igual que cuando iba todos los días a la oficina | AB4: Igual que cuando iba todos los días a la oficina | AC4: Igual que cuando iba todos los días a la oficina | AD4: Iguales que cuando iba todos los días a la oficina | AE4: Todas por videoconferencia | AF4: Igual que cuando eran en la oficina | AG4: Mayor que cuando iba todos los días a la oficina | AH4: Mucho Mayor que cuando iba todos los días a la oficina | AI4: Mayor que cuando iba todos los días a la oficina | AJ4: Mayor que cuando iba todos los días a la oficina | AK4: Igual que cuando iba todos los días a la oficina | AL4: Mejora mi desempeño en el trabajo | AM4: Mejoran mi productividad | AN4: Igual que cuando iba todos los días a la oficina | AO4: Igual que cuando iba todos los días a la oficina | AP4: Igual que cuando iba todos los días a la oficina | AQ4: Igual que cuando iba todos los días a la oficina | AR4: Igual que cuando iba todos los días a la oficina | AS4: Igual que cuando iba todos los días a la oficina | AT4: Igual que cuando iba todos los días a la oficina | AU4: Igual que cuando iba todos los días a la oficina | AV4: Igual que cuando iba todos los días a la oficina | AW4: Igual que cuando iba todos los días a la oficina | AX4: Igual que cuando iba todos los días a la oficina | AY4: Iguales que cuando iba todos los días a la oficina | AZ4: Igual que cuando iba todos los días a la oficina | BA4: Igual que cuando iba todos los días a la oficina | BB4: Igual que cuando iba todos los días a la oficina | BC4: Igual que cuando iba todos los días a la oficina | BD4: Igual que cuando iba todos los días a la oficina | BE4: Igual que cuando iba todos los días a la oficina | BF4: Igual que cuando iba todos los días a la oficina | BG4: Igual que cuando iba todos los días a la oficina | BH4: Iguales que cuando iba todos los días a la oficina | BI4: Igual que cuando iba todos los días a la oficina | BJ4: Iguales que cuando iba todos los días a la oficina | BK4: Mayor que cuando iba todos los días a la oficina | BL4: Iguales que cuando iba todos los días a la oficina | BM4: Iguales que cuando iba todos los días a la oficina | BN4: Igual que cuando iba todos los días a la oficina | BO4: Igual que cuando iba todos los días a la oficina | BP4: Iguales que cuando iba todos los días a la oficina | BQ4: Igual que cuando iba todos los días a la oficina | BR4: Igual que cuando iba todos los días a la oficina | BS4: Igual que cuando iba todos los días a la oficina | BT4: Iguales que cuando iba todos los días a la oficina | BU4: Igual que cuando iba todos los días a la oficina | BV4: Igual que cuando iba todos los días a la oficina | BW4: Mayor que cuando iba todos los días a la oficina | BX4: Mayor que cuando iba todos los días a la oficina | BY4: Igual que cuando iba todos los días a la oficina | BZ4: Igual que cuando iba todos los días a la oficina | CA4: Igual que cuando iba todos los días a la oficina | CB4: Igual que cuando iba todos los días a la oficina | CC4: Igual que cuando iba todos los días a la oficina | CD4: Igual que cuando iba todos los días a la oficina | CE4: Igual que cuando iba todos los días a la oficina | CF4: Iguales que cuando iba todos los días a la oficina | CG4: Igual que cuando iba todos los días a la oficina | CH4: Igual que cuando iba todos los días a la oficina | CI4: Igual que cuando iba todos los días a la oficina | CJ4: Igual que cuando iba todos los días a la oficina | CK4: Igual que cuando iba todos los días a la oficina | CL4: Igual que cuando iba todos los días a la oficina | CM4: Igual que cuando iba todos los días a la oficina | CN4: Igual que cuando iba todos los días a la oficina | CO4: Igual que cuando iba todos los días a la oficina | CP4: Igual que cuando iba todos los días a la oficina | CQ4: Igual que cuando iba todos los días a la oficina | CR4: Igual que cuando iba todos los días a la oficina | CS4: Iguales que cuando iba todos los días a la oficina | CT4: Igual que cuando iba todos los días a la oficina | CU4: Igual que cuando iba todos los días a la oficina | CV4: de.escobarc1@uniandes.edu.co | CW4: <301 empleados | CX4: =VLOOKUP(K4,Sheet2!$A$2:$B$58,2,0) -> 0 | CY4: =_xlfn.TEXTJOIN(",",FALSE,A4:CX4) -> 45573,063303044,Colombia,<35 años,Masculino,Profesional,Como empleado de una empresa,Bogotá ,5-10 años,5-10 años,Desarollador junior,Líder técnico de desarrollo,Lulo bank,151-300 empleados,Empresa que desarrolla software a medida partiendo desde cero,Local,Casi Nunca,Alto,>5 días,Ninguno,A integraciones de trabajo,,,,Remota ( todos los días en casa),Impuesta por la empresa,Totalmente en desacuerdo,Igual que cuando iba todos los días a la oficina,Igual que cuando iba todos los días a la oficina,Igual que cuando iba todos los días a la oficina,Iguales que cuando iba todos los días a la oficina,Todas por videoconferencia,Igual que cuando eran en la oficina,Mayor que cuando iba todos los días a la oficina,Mucho Mayor que cuando iba todos los días a la oficina,Mayor que cuando iba todos los días a la oficina,Mayor que cuando iba todos los días a la oficina,Igual que cuando iba todos los días a la oficina,Mejora mi desempeño en el trabajo,Mejoran mi productividad,Igual que cuando iba todos los días a la oficina,Igual que cuando iba todos los días a la oficina,Igual que cuando iba todos los días a la oficina,Igual que cuando iba todos los días a la oficina,Igual que cuando iba todos los días a la oficina,Igual que cuando iba todos los días a la oficina,Igual que cuando iba todos los días a la oficina,Igual que cuando iba todos los días a la oficina,Igual que cuando iba todos los días a la oficina,Igual que cuando iba todos los días a la oficina,Igual que cuando iba todos los días a la oficina,Iguales que cuando iba todos los días a la oficina,Igual que cuando iba todos los días a la oficina,Igual que cuando iba todos los días a la oficina,Igual que cuando iba todos los días a la oficina,Igual que cuando iba todos los días a la oficina,Igual que cuando iba todos los días a la oficina,Igual que cuando iba todos los días a la oficina,Igual que cuando iba todos los días a la oficina,Igual que cuando iba todos los días a la oficina,Iguales que cuando iba todos los días a la oficina,Igual que cuando iba todos los días a la oficina,Iguales que cuando iba todos los días a la oficina,Mayor que cuando iba todos los días a la oficina,Iguales que cuando iba todos los días a la oficina,Iguales que cuando iba todos los días a la oficina,Igual que cuando iba todos los días a la oficina,Igual que cuando iba todos los días a la oficina,Iguales que cuando iba todos los días a la oficina,Igual que cuando iba todos los días a la oficina,Igual que cuando iba todos los días a la oficina,Igual que cuando iba todos los días a la oficina,Iguales que cuando iba todos los días a la oficina,Igual que cuando iba todos los días a la oficina,Igual que cuando iba todos los días a la oficina,Mayor que cuando iba todos los días a la oficina,Mayor que cuando iba todos los días a la oficina,Igual que cuando iba todos los días a la oficina,Igual que cuando iba todos los días a la oficina,Igual que cuando iba todos los días a la oficina,Igual que cuando iba todos los días a la oficina,Igual que cuando iba todos los días a la oficina,Igual que cuando iba todos los días a la oficina,Igual que cuando iba todos los días a la oficina,Iguales que cuando iba todos los días a la oficina,Igual que cuando iba todos los días a la oficina,Igual que cuando iba todos los días a la oficina,Igual que cuando iba todos los días a la oficina,Igual que cuando iba todos los días a la oficina,Igual que cuando iba todos los días a la oficina,Igual que cuando iba todos los días a la oficina,Igual que cuando iba todos los días a la oficina,Igual que cuando iba todos los días a la oficina,Igual que cuando iba todos los días a la oficina,Igual que cuando iba todos los días a la oficina,Igual que cuando iba todos los días a la oficina,Igual que cuando iba todos los días a la oficina,Iguales que cuando iba todos los días a la oficina,Igual que cuando iba todos los días a la oficina,Igual que cuando iba todos los días a la oficina,de.escobarc1@uniandes.edu.co,<301 empleados,0
A5: 45562.001 | B5: Colombia | C5: <35 años | D5: Masculino | E5: Postgrado | F5: Como empleado de una empresa | G5: Colombia | H5: 5-10 años | I5: <5 años | J5: Desarrollador de Software | K5: Tech Lead | L5: Asesoftware | M5: 301-500 empleados | N5: Fábrica de Software | O5: Local | P5: Casi Nunca | Q5: Alto | R5: >5 días | S5: Ninguno | T5: Reuniones con cliente | V5: Reuniones de seguimiento o con cliente | X5: Remota ( todos los días en casa) | Y5: Consensuada por las dos partes | Z5: De acuerdo | AA5: Igual que cuando iba todos los días a la oficina | AB5: Igual que cuando iba todos los días a la oficina | AC5: Igual que cuando iba todos los días a la oficina | AD5: Iguales que cuando iba todos los días a la oficina | AE5: Casi todas por videoconferencia | AF5: Menor que cuando eran en la oficina | AG5: Mayor que cuando iba todos los días a la oficina | AH5: Igual que cuando iba todos los días a la oficina | AI5: Igual que cuando iba todos los días a la oficina | AJ5: Igual que cuando iba todos los días a la oficina | AK5: Mucho Mejor que cuando iba todos los días a la oficina | AL5: Mejora mi desempeño en el trabajo | AM5: No afectan a mi productividad | AN5: Igual que cuando iba todos los días a la oficina | AO5: Menor que cuando iba todos los días a la oficina | AP5: Igual que cuando iba todos los días a la oficina | AQ5: Igual que cuando iba todos los días a la oficina | AR5: No trabajo con personas con un horario distinto al mío | AS5: Igual que cuando iba todos los días a la oficina | AT5: No tengo la información para contestar a la pregunta | AU5: Menos que cuando iba todos los días a la oficina | AV5: Igual que cuando iba todos los días a la oficina | AW5: Igual que cuando iba todos los días a la oficina | AX5: Igual que cuando iba todos los días a la oficina | AY5: Iguales que cuando iba todos los días a la oficina | AZ5: Igual que cuando iba todos los días a la oficina | BA5: Igual que cuando iba todos los días a la oficina | BB5: Menor que cuando iba todos los días a la oficina | BC5: Mayor que cuando iba todos los días a la oficina | BD5: Menor que cuando iba todos los días a la oficina | BE5: Menor que cuando iba todos los días a la oficina | BF5: Igual que cuando iba todos los días a la oficina | BG5: Mucho mayor que cuando iba todos los días a la oficina | BH5: Mucho menores que cuando iba todos los días a la oficina | BI5: Igual que cuando iba todos los días a la oficina | BJ5: No hay diferencias culturales en mi equipo | BK5: Igual que cuando iba todos los días a la oficina | BL5: Iguales que cuando iba todos los días a la oficina | BM5: No tengo que utilizar diferentes idiomas en mi trabajo | BN5: No trabajo con personas con distintos horarios | BO5: Igual que cuando iba todos los días a la oficina | BP5: Mucho menores que cuando iba todos los días a la oficina | BQ5: Mucho mayor que cuando iba todos los días a la oficina | BR5: Igual que cuando iba todos los días a la oficina | BS5: No tengo la información para contestar a la pregunta | BT5: Iguales que cuando iba todos los días a la oficina | BU5: Igual que cuando iba todos los días a la oficina | BV5: Mucho Mayor que cuando iba todos los días a la oficina | BW5: Mucho Mayor que cuando iba todos los días a la oficina | BX5: Mucho mayor que cuando iba todos los días a la oficina | BY5: Mayor que cuando iba todos los días a la oficina | BZ5: Igual que cuando iba todos los días a la oficina | CA5: Mayor que cuando iba todos los días a la oficina | CB5: Mucho Mayor que cuando iba todos los días a la oficina | CC5: Mucho Mayor que cuando iba todos los días a la oficina | CD5: Igual que cuando iba todos los días a la oficina | CE5: Igual que cuando iba todos los días a la oficina | CF5: Menores que cuando iba todos los días a la oficina | CG5: Igual que cuando iba todos los días a la oficina | CH5: Mayor que cuando iba todos los días a la oficina | CI5: Igual que cuando iba todos los días a la oficina | CJ5: Menor que cuando iba todos los días a la oficina | CK5: Igual que cuando iba todos los días a la oficina | CL5: Igual que cuando iba todos los días a la oficina | CM5: Mejor que cuando iba todos los días a la oficina | CN5: Igual que cuando iba todos los días a la oficina | CO5: Igual que cuando iba todos los días a la oficina | CP5: Igual que cuando iba todos los días a la oficina | CQ5: Mucho Mayor que cuando iba todos los días a la oficina | CR5: Mucho menor que cuando iba todos los días a la oficina | CS5: Iguales que cuando iba todos los días a la oficina | CT5: Igual que cuando iba todos los días a la oficina | CU5: Mucho mayor que cuando iba todos los días a la oficina | CV5: xavigonpa@gmail.com | CW5: 301+ empleados | CX5: =VLOOKUP(K5,Sheet2!$A$2:$B$58,2,0) -> 0 | CY5: =_xlfn.TEXTJOIN(",",FALSE,A5:CX5) -> 45562,0007543056,Colombia,<35 años,Masculino,Postgrado,Como empleado de una empresa,Colombia,5-10 años,<5 años,Desarrollador de Software,Tech Lead,Asesoftware,301-500 empleados,Fábrica de Software,Local,Casi Nunca,Alto,>5 días,Ninguno,Reuniones con cliente,,Reuniones de seguimiento o con cliente,,Remota ( todos los días en casa),Consensuada por las dos partes,De acuerdo,Igual que cuando iba todos los días a la oficina,Igual que cuando iba todos los días a la oficina,Igual que cuando iba todos los días a la oficina,Iguales que cuando iba todos los días a la oficina,Casi todas por videoconferencia,Menor que cuando eran en la oficina,Mayor que cuando iba todos los días a la oficina,Igual que cuando iba todos los días a la oficina,Igual que cuando iba todos los días a la oficina,Igual que cuando iba todos los días a la oficina,Mucho Mejor que cuando iba todos los días a la oficina,Mejora mi desempeño en el trabajo,No afectan a mi productividad,Igual que cuando iba todos los días a la oficina,Menor que cuando iba todos los días a la oficina,Igual que cuando iba todos los días a la oficina,Igual que cuando iba todos los días a la oficina,No trabajo con personas con un horario distinto al mío,Igual que cuando iba todos los días a la oficina,No tengo la información para contestar a la pregunta,Menos que cuando iba todos los días a la oficina,Igual que cuando iba todos los días a la oficina,Igual que cuando iba todos los días a la oficina,Igual que cuando iba todos los días a la oficina,Iguales que cuando iba todos los días a la oficina,Igual que cuando iba todos los días a la oficina,Igual que cuando iba todos los días a la oficina,Menor que cuando iba todos los días a la oficina,Mayor que cuando iba todos los días a la oficina,Menor que cuando iba todos los días a la oficina,Menor que cuando iba todos los días a la oficina,Igual que cuando iba todos los días a la oficina,Mucho mayor que cuando iba todos los días a la oficina,Mucho menores que cuando iba todos los días a la oficina,Igual que cuando iba todos los días a la oficina,No hay diferencias culturales en mi equipo,Igual que cuando iba todos los días a la oficina,Iguales que cuando iba todos los días a la oficina,No tengo que utilizar diferentes idiomas en mi trabajo,No trabajo con personas con distintos horarios,Igual que cuando iba todos los días a la oficina,Mucho menores que cuando iba todos los días a la oficina,Mucho mayor que cuando iba todos los días a la oficina,Igual que cuando iba todos los días a la oficina,No tengo la información para contestar a la pregunta,Iguales que cuando iba todos los días a la oficina,Igual que cuando iba todos los días a la oficina,Mucho Mayor que cuando iba todos los días a la oficina,Mucho Mayor que cuando iba todos los días a la oficina,Mucho mayor que cuando iba todos los días a la oficina,Mayor que cuando iba todos los días a la oficina,Igual que cuando iba todos los días a la oficina,Mayor que cuando iba todos los días a la oficina,Mucho Mayor que cuando iba todos los días a la oficina,Mucho Mayor que cuando iba todos los días a la oficina,Igual que cuando iba todos los días a la oficina,Igual que cuando iba todos los días a la oficina,Menores que cuando iba todos los días a la oficina,Igual que cuando iba todos los días a la oficina,Mayor que cuando iba todos los días a la oficina,Igual que cuando iba todos los días a la oficina,Menor que cuando iba todos los días a la oficina,Igual que cuando iba todos los días a la oficina,Igual que cuando iba todos los días a la oficina,Mejor que cuando iba todos los días a la oficina,Igual que cuando iba todos los días a la oficina,Igual que cuando iba todos los días a la oficina,Igual que cuando iba todos los días a la oficina,Mucho Mayor que cuando iba todos los días a la oficina,Mucho menor que cuando iba todos los días a la oficina,Iguales que cuando iba todos los días a la oficina,Igual que cuando iba todos los días a la oficina,Mucho mayor que cuando iba todos los días a la oficina,xavigonpa@gmail.com,301+ empleados,0
A6: 45564.76 | B6: Colombia | C6: <35 años | D6: Masculino | E6: Profesional | F6: Como empleado de una empresa | G6: Colombia | H6: 11-20 años | I6: 5-10 años | J6: Desarrollador Senior y Líder Técnico | K6: Director de Tecnología y Desarrollo de Software | L6: Crediestado | M6: <50 empleados | N6: Empresa que desarrolla software a medida partiendo desde cero | O6: Nacional (múltiples sedes en el mismo país) | P6: Nunca | Q6: Alto | R6: >5 días | S6: Ninguno | T6: No, sin embargo me solicitan ir en momentos extremadamente necesario | W6: Considero que sería complejo, en casa soy feliz y tengo más tiempo para dedicar a mi trabajo y en unos pocos minutos hacer cambio a mis actividades personales. En el caso extremo de tener que asistir a la oficina, esperaría tener una oficina bonita, parqueadero, y una buena cafetería para asistir. | X6: Remota ( todos los días en casa) | Y6: Consensuada por las dos partes | Z6: En desacuerdo | AA6: Mucho mayor que cuando iba todos los días a la oficina | AB6: Mayor que cuando iba todos los días a la oficina | AC6: Igual que cuando iba todos los días a la oficina | AD6: Diferentes que cuando iba todos los días a la oficina, ahora necesito menos horas para hacer lo mismo | AE6: Todas por videoconferencia | AF6: Mucho menor que cuando eran en la oficina | AG6: Mayor que cuando iba todos los días a la oficina | AH6: Mucho Mayor que cuando iba todos los días a la oficina | AI6: Mucho Mayor que cuando iba todos los días a la oficina | AJ6: Mayor que cuando iba todos los días a la oficina | AK6: Igual que cuando iba todos los días a la oficina | AL6: Mejora mi desempeño en el trabajo | AM6: No afectan a mi productividad | AN6: Mayor que cuando iba todos los días a la oficina | AO6: Mucho menor que cuando iba todos los días a la oficina | AP6: Mucho menos que cuando iba todos los días a la oficina | AQ6: No trabajo con personas de distintas culturas | AR6: No trabajo con personas con un horario distinto al mío | AS6: No trabajo con personas que se encuentran geográficamente distribuidas | AT6: Menos que cuando iba todos los días a la oficina | AU6: Menos que cuando iba todos los días a la oficina | AV6: No tengo la información para contestar a la pregunta | AW6: Menos que cuando iba todos los días a la oficina | AX6: Menos que cuando iba todos los días a la oficina | AY6: Mayores que cuando iba todos los días a la oficina | AZ6: Mayor que cuando iba todos los días a la oficina | BA6: Mucho Mayor que cuando iba todos los días a la oficina | BB6: Menor que cuando iba todos los días a la oficina | BC6: Mayor que cuando iba todos los días a la oficina | BD6: Menor que cuando iba todos los días a la oficina | BE6: Menor que cuando iba todos los días a la oficina | BF6: Menor que cuando iba todos los días a la oficina | BG6: Mucho mayor que cuando iba todos los días a la oficina | BH6: Iguales que cuando iba todos los días a la oficina | BI6: Mayor que cuando iba todos los días a la oficina | BJ6: No hay diferencias culturales en mi equipo | BK6: Mayor que cuando iba todos los días a la oficina | BL6: Menores que cuando iba todos los días a la oficina | BM6: No tengo que utilizar diferentes idiomas en mi trabajo | BN6: No trabajo con personas con distintos horarios | BO6: Mucho mayor que cuando iba todos los días a la oficina | BP6: Menores que cuando iba todos los días a la oficina | BQ6: Mucho mayor que cuando iba todos los días a la oficina | BR6: Menor que cuando iba todos los días a la oficina | BS6: Menos que cuando iba todos los días a la oficina | BT6: Menores que cuando iba todos los días a la oficina | BU6: Mejor que cuando iba todos los días a la oficina | BV6: Mucho Mayor que cuando iba todos los días a la oficina | BW6: Mayor que cuando iba todos los días a la oficina | BX6: Mayor que cuando iba todos los días a la oficina | BY6: Igual que cuando iba todos los días a la oficina | BZ6: Igual que cuando iba todos los días a la oficina | CA6: Mayor que cuando iba todos los días a la oficina | CB6: Mucho Mayor que cuando iba todos los días a la oficina | CC6: Mayor que cuando iba todos los días a la oficina | CD6: Menor que cuando iba todos los días a la oficina | CE6: Mas que cuando iba todos los días a la oficina | CF6: Iguales que cuando iba todos los días a la oficina | CG6: Mayor que cuando iba todos los días a la oficina | CH6: Mucho Mayor que cuando iba todos los días a la oficina | CI6: Mayor que cuando iba todos los días a la oficina | CJ6: Mucho menor que cuando iba todos los días a la oficina | CK6: Mayor que cuando iba todos los días a la oficina | CL6: Igual que cuando iba todos los días a la oficina | CM6: Mejor que cuando iba todos los días a la oficina | CN6: Mucho Mayor que cuando iba todos los días a la oficina | CO6: Mayor que cuando iba todos los días a la oficina | CP6: Mayor que cuando iba todos los días a la oficina | CQ6: Mucho Mayor que cuando iba todos los días a la oficina | CR6: Menor que cuando iba todos los días a la oficina | CS6: Menores que cuando iba todos los días a la oficina | CT6: Mucho Mayor que cuando iba todos los días a la oficina | CU6: Mayor que cuando iba todos los días a la oficina | CV6: miguel.vega.ruiz@gmail.com | CW6: <301 empleados | CX6: =VLOOKUP(K6,Sheet2!$A$2:$B$58,2,0) -> 0 | CY6: =_xlfn.TEXTJOIN(",",FALSE,A6:CX6) -> 45564,7603757292,Colombia,<35 años,Masculino,Profesional,Como empleado de una empresa,Colombia,11-20 años,5-10 años,Desarrollador Senior y Líder Técnico,Director de Tecnología y Desarrollo de Software,Crediestado,<50 empleados,Empresa que desarrolla software a medida partiendo desde cero,Nacional (múltiples sedes en el mismo país),Nunca,Alto,>5 días,Ninguno,No, sin embargo me solicitan ir en momentos extremadamente necesario,,,Considero que sería complejo, en casa soy feliz y tengo más tiempo para dedicar a mi trabajo y en unos pocos minutos hacer cambio a mis actividades personales. En el caso extremo de tener que asistir a la oficina, esperaría tener una oficina bonita, parqueadero, y una buena cafetería para asistir.,Remota ( todos los días en casa),Consensuada por las dos partes,En desacuerdo,Mucho mayor que cuando iba todos los días a la oficina,Mayor que cuando iba todos los días a la oficina,Igual que cuando iba todos los días a la oficina,Diferentes que cuando iba todos los días a la oficina, ahora necesito menos horas para hacer lo mismo,Todas por videoconferencia,Mucho menor que cuando eran en la oficina,Mayor que cuando iba todos los días a la oficina,Mucho Mayor que cuando iba todos los días a la oficina,Mucho Mayor que cuando iba todos los días a la oficina,Mayor que cuando iba todos los días a la oficina,Igual que cuando iba todos los días a la oficina,Mejora mi desempeño en el trabajo,No afectan a mi productividad,Mayor que cuando iba todos los días a la oficina,Mucho menor que cuando iba todos los días a la oficina,Mucho menos que cuando iba todos los días a la oficina,No trabajo con personas de distintas culturas,No trabajo con personas con un horario distinto al mío,No trabajo con personas que se encuentran geográficamente distribuidas,Menos que cuando iba todos los días a la oficina,Menos que cuando iba todos los días a la oficina,No tengo la información para contestar a la pregunta,Menos que cuando iba todos los días a la oficina,Menos que cuando iba todos los días a la oficina,Mayores que cuando iba todos los días a la oficina,Mayor que cuando iba todos los días a la oficina,Mucho Mayor que cuando iba todos los días a la oficina,Menor que cuando iba todos los días a la oficina,Mayor que cuando iba todos los días a la oficina,Menor que cuando iba todos los días a la oficina,Menor que cuando iba todos los días a la oficina,Menor que cuando iba todos los días a la oficina,Mucho mayor que cuando iba todos los días a la oficina,Iguales que cuando iba todos los días a la oficina,Mayor que cuando iba todos los días a la oficina,No hay diferencias culturales en mi equipo,Mayor que cuando iba todos los días a la oficina,Menores que cuando iba todos los días a la oficina,No tengo que utilizar diferentes idiomas en mi trabajo,No trabajo con personas con distintos horarios,Mucho mayor que cuando iba todos los días a la oficina,Menores que cuando iba todos los días a la oficina,Mucho mayor que cuando iba todos los días a la oficina,Menor que cuando iba todos los días a la oficina,Menos que cuando iba todos los días a la oficina,Menores que cuando iba todos los días a la oficina,Mejor que cuando iba todos los días a la oficina,Mucho Mayor que cuando iba todos los días a la oficina,Mayor que cuando iba todos los días a la oficina,Mayor que cuando iba todos los días a la oficina,Igual que cuando iba todos los días a la oficina,Igual que cuando iba todos los días a la oficina,Mayor que cuando iba todos los días a la oficina,Mucho Mayor que cuando iba todos los días a la oficina,Mayor que cuando iba todos los días a la oficina,Menor que cuando iba todos los días a la oficina,Mas que cuando iba todos los días a la oficina,Iguales que cuando iba todos los días a la oficina,Mayor que cuando iba todos los días a la oficina,Mucho Mayor que cuando iba todos los días a la oficina,Mayor que cuando iba todos los días a la oficina,Mucho menor que cuando iba todos los días a la oficina,Mayor que cuando iba todos los días a la oficina,Igual que cuando iba todos los días a la oficina,Mejor que cuando iba todos los días a la oficina,Mucho Mayor que cuando iba todos los días a la oficina,Mayor que cuando iba todos los días a la oficina,Mayor que cuando iba todos los días a la oficina,Mucho Mayor que cuando iba todos los días a la oficina,Menor que cuando iba todos los días a la oficina,Menores que cuando iba todos los días a la oficina,Mucho Mayor que cuando iba todos los días a la oficina,Mayor que cuando iba todos los días a la oficina,miguel.vega.ruiz@gmail.com,<301 empleados,0
